Workbook

Sheet 各勝率等
A1: プレイヤー | B1: えいご | C1: おうた | D1: かいと | E1: きむら | F1: きむら
A2: 参加数 | B2: #ERROR!

Sheet 20250520
A1: プレイヤー名 | B1: だいち | C1: えいご | D1: かいと | F1: 合計 | G1: 点数チェック
A2: 1 ゲーム目 | B2: 79000 | C2: -4000 | D2: 30000 | F2: =SUM($B2:$E2) -> 105000 | G2: =_xludf.IFS(COUNT($B2:$E2)=0, "", $F2>$B$17*$B$20, マスタ!$A$2, $F2<$B$17*$B$20, マスタ!$A$3, TRUE, "正常") -> #NAME?
A3: 2 ゲーム目 | B3: 78000 | C3: -10000 | D3: 37000 | F3: =SUM($B3:$E3) -> 105000 | G3: =_xludf.IFS(COUNT($B3:$E3)=0, "", $F3>$B$17*$B$20, マスタ!$A$2, $F3<$B$17*$B$20, マスタ!$A$3, TRUE, "正常") -> #NAME?
A4: 3 ゲーム目 | B4: 29000 | C4: 9000 | D4: 67000 | F4: =SUM($B4:$E4) -> 105000 | G4: =_xludf.IFS(COUNT($B4:$E4)=0, "", $F4>$B$17*$B$20, マスタ!$A$2, $F4<$B$17*$B$20, マスタ!$A$3, TRUE, "正常") -> #NAME?
A5: 4 ゲーム目 | B5: 22000 | C5: 33000 | D5: 50000 | F5: =SUM($B5:$E5) -> 105000 | G5: =_xludf.IFS(COUNT($B5:$E5)=0, "", $F5>$B$17*$B$20, マスタ!$A$2, $F5<$B$17*$B$20, マスタ!$A$3, TRUE, "正常") -> #NAME?
A6: 5 ゲーム目 | F6: =SUM($B6:$E6) -> 0 | G6: =_xludf.IFS(COUNT($B6:$E6)=0, "", $F6>$B$17*$B$20, マスタ!$A$2, $F6<$B$17*$B$20, マスタ!$A$3, TRUE, "正常") -> #NAME?
A7: 6 ゲーム目 | F7: =SUM($B7:$E7) -> 0 | G7: =_xludf.IFS(COUNT($B7:$E7)=0, "", $F7>$B$17*$B$20, マスタ!$A$2, $F7<$B$17*$B$20, マスタ!$A$3, TRUE, "正常") -> #NAME?
A8: 7 ゲーム目 | F8: =SUM($B8:$E8) -> 0 | G8: =_xludf.IFS(COUNT($B8:$E8)=0, "", $F8>$B$17*$B$20, マスタ!$A$2, $F8<$B$17*$B$20, マスタ!$A$3, TRUE, "正常") -> #NAME?
A9: 8 ゲーム目 | F9: =SUM($B9:$E9) -> 0 | G9: =_xludf.IFS(COUNT($B9:$E9)=0, "", $F9>$B$17*$B$20, マスタ!$A$2, $F9<$B$17*$B$20, マスタ!$A$3, TRUE, "正常") -> #NAME?
A10: 9 ゲーム目 | F10: =SUM($B10:$E10) -> 0 | G10: =_xludf.IFS(COUNT($B10:$E10)=0, "", $F10>$B$17*$B$20, マスタ!$A$2, $F10<$B$17*$B$20, マスタ!$A$3, TRUE, "正常") -> #NAME?
A11: 10 ゲーム目 | F11: =SUM($B11:$E11) -> 0 | G11: =_xludf.IFS(COUNT($B11:$E11)=0, "", $F11>$B$17*$B$20, マスタ!$A$2, $F11<$B$17*$B$20, マスタ!$A$3, TRUE, "正常") -> #NAME?
A12: 合計 | B12: =SUM(B$2:B$11) -> 208000 | C12: =SUM(C$2:C$11) -> 28000 | D12: =SUM(D$2:D$11) -> 184000 | E12: =IF(COUNTA(E$1), SUM(E$2:E$11), "-") -> - | F12: =SUM($B12:$E12) -> 420000 | G12: =_xludf.IFS($F$12>$B$17*$B$20*$B$21, マスタ!$A$2, $F$12<$B$17*$B$20*$B$21, マスタ!$A$3, TRUE, "正常") -> #NAME?
A13: 増減 | B13: =B12-$B17*$B$21 -> 68000 | C13: =C12-$B17*$B$21 -> -112000 | D13: =D12-$B17*$B$21 -> 44000 | E13: =IF(COUNTA(E$1), E12-$B17*$B$21, "-") -> - | F13: =SUM($B13:$E13) -> 0 | G13: -
A14: 清算 | B14: =B$13*$B$18 -> 3400 | C14: =C$13*$B$18 -> -5600 | D14: =D$13*$B$18 -> 2200 | E14: =IF(COUNTA(E$1), E$13*$B$18, "-") -> - | F14: =SUM($B14:$E14) -> 0 | G14: -
A15: 順位 | B15: =RANK(B$14, $B$14:$E$14) -> 1 | C15: =RANK(C$14, $B$14:$E$14) -> 3 | D15: =RANK(D$14, $B$14:$E$14) -> 2 | E15: =IF(COUNTA(E$1), RANK(E$14, $B$14:$E$14), "-") -> - | F15: =SUM($B15:$E15) -> 6 | G15: -
A17: 持ち点 | B17: 35000
A18: レート | B18: 0.05
A20: プレイヤー数 | B20: =COUNTA($B$1:$E$1) -> 3
A21: ゲーム数 | B21: =COUNT($B$2:$B$11) -> 4
A22: 合計点 | B22: =$B$17*$B$20*$B$21 -> 420000

Sheet 20250521
A1: プレイヤー名 | B1: きむら | C1: だいち | D1: かいと | F1: 合計 | G1: 点数チェック
A2: 1 ゲーム目 | B2: -2000 | C2: 39000 | D2: 68000 | F2: =SUM($B2:$E2) -> 105000 | G2: =_xludf.IFS(COUNT($B2:$E2)=0, "", $F2>$B$17*$B$20, マスタ!$A$2, $F2<$B$17*$B$20, マスタ!$A$3, TRUE, "正常") -> #NAME?
A3: 2 ゲーム目 | B3: 86000 | C3: 42000 | D3: -23000 | F3: =SUM($B3:$E3) -> 105000 | G3: =_xludf.IFS(COUNT($B3:$E3)=0, "", $F3>$B$17*$B$20, マスタ!$A$2, $F3<$B$17*$B$20, マスタ!$A$3, TRUE, "正常") -> #NAME?
A4: 3 ゲーム目 | B4: 33000 | C4: 30000 | D4: 42000 | F4: =SUM($B4:$E4) -> 105000 | G4: =_xludf.IFS(COUNT($B4:$E4)=0, "", $F4>$B$17*$B$20, マスタ!$A$2, $F4<$B$17*$B$20, マスタ!$A$3, TRUE, "正常") -> #NAME?
A5: 4 ゲーム目 | F5: =SUM($B5:$E5) -> 0 | G5: =_xludf.IFS(COUNT($B5:$E5)=0, "", $F5>$B$17*$B$20, マスタ!$A$2, $F5<$B$17*$B$20, マスタ!$A$3, TRUE, "正常") -> #NAME?
A6: 5 ゲーム目 | F6: =SUM($B6:$E6) -> 0 | G6: =_xludf.IFS(COUNT($B6:$E6)=0, "", $F6>$B$17*$B$20, マスタ!$A$2, $F6<$B$17*$B$20, マスタ!$A$3, TRUE, "正常") -> #NAME?
A7: 6 ゲーム目 | F7: =SUM($B7:$E7) -> 0 | G7: =_xludf.IFS(COUNT($B7:$E7)=0, "", $F7>$B$17*$B$20, マスタ!$A$2, $F7<$B$17*$B$20, マスタ!$A$3, TRUE, "正常") -> #NAME?
A8: 7 ゲーム目 | F8: =SUM($B8:$E8) -> 0 | G8: =_xludf.IFS(COUNT($B8:$E8)=0, "", $F8>$B$17*$B$20, マスタ!$A$2, $F8<$B$17*$B$20, マスタ!$A$3, TRUE, "正常") -> #NAME?
A9: 8 ゲーム目 | F9: =SUM($B9:$E9) -> 0 | G9: =_xludf.IFS(COUNT($B9:$E9)=0, "", $F9>$B$17*$B$20, マスタ!$A$2, $F9<$B$17*$B$20, マスタ!$A$3, TRUE, "正常") -> #NAME?
A10: 9 ゲーム目 | F10: =SUM($B10:$E10) -> 0 | G10: =_xludf.IFS(COUNT($B10:$E10)=0, "", $F10>$B$17*$B$20, マスタ!$A$2, $F10<$B$17*$B$20, マスタ!$A$3, TRUE, "正常") -> #NAME?
A11: 10 ゲーム目 | F11: =SUM($B11:$E11) -> 0 | G11: =_xludf.IFS(COUNT($B11:$E11)=0, "", $F11>$B$17*$B$20, マスタ!$A$2, $F11<$B$17*$B$20, マスタ!$A$3, TRUE, "正常") -> #NAME?
A12: 合計 | B12: =SUM(B$2:B$11) -> 117000 | C12: =SUM(C$2:C$11) -> 111000 | D12: =SUM(D$2:D$11) -> 87000 | E12: =IF(COUNTA(E$1), SUM(E$2:E$11), "-") -> - | F12: =SUM($B12:$E12) -> 315000 | G12: =_xludf.IFS($F$12>$B$17*$B$20*$B$21, マスタ!$A$2, $F$12<$B$17*$B$20*$B$21, マスタ!$A$3, TRUE, "正常") -> #NAME?
A13: 増減 | B13: =B12-$B17*$B$21 -> 12000 | C13: =C12-$B17*$B$21 -> 6000 | D13: =D12-$B17*$B$21 -> -18000 | E13: =IF(COUNTA(E$1), E12-$B17*$B$21, "-") -> - | F13: =SUM($B13:$E13) -> 0 | G13: -
A14: 清算 | B14: =B$13*$B$18 -> 600 | C14: =C$13*$B$18 -> 300 | D14: =D$13*$B$18 -> -900 | E14: =IF(COUNTA(E$1), E$13*$B$18, "-") -> - | F14: =SUM($B14:$E14) -> 0 | G14: -
A15: 順位 | B15: =RANK(B$14, $B$14:$E$14) -> 1 | C15: =RANK(C$14, $B$14:$E$14) -> 2 | D15: =RANK(D$14, $B$14:$E$14) -> 3 | E15: =IF(COUNTA(E$1), RANK(E$14, $B$14:$E$14), "-") -> - | F15: =SUM($B15:$E15) -> 6 | G15: -
A17: 持ち点 | B17: 35000
A18: レート | B18: 0.05
A20: プレイヤー数 | B20: =COUNTA($B$1:$E$1) -> 3
A21: ゲーム数 | B21: =COUNT($B$2:$B$11) -> 3
A22: 合計点 | B22: =$B$17*$B$20*$B$21 -> 315000

Sheet 20250524
A1: プレイヤー名 | B1: おうた | C1: だいち | D1: かいと | F1: 合計 | G1: 点数チェック
A2: 1 ゲーム目 | B2: 2000 | C2: 20000 | D2: 83000 | F2: =SUM($B2:$E2) -> 105000 | G2: =_xludf.IFS(COUNT($B2:$E2)=0, "", $F2>$B$17*$B$20, マスタ!$A$2, $F2<$B$17*$B$20, マスタ!$A$3, TRUE, "正常") -> #NAME?
A3: 2 ゲーム目 | F3: =SUM($B3:$E3) -> 0 | G3: =_xludf.IFS(COUNT($B3:$E3)=0, "", $F3>$B$17*$B$20, マスタ!$A$2, $F3<$B$17*$B$20, マスタ!$A$3, TRUE, "正常") -> #NAME?
A4: 3 ゲーム目 | F4: =SUM($B4:$E4) -> 0 | G4: =_xludf.IFS(COUNT($B4:$E4)=0, "", $F4>$B$17*$B$20, マスタ!$A$2, $F4<$B$17*$B$20, マスタ!$A$3, TRUE, "正常") -> #NAME?
A5: 4 ゲーム目 | F5: =SUM($B5:$E5) -> 0 | G5: =_xludf.IFS(COUNT($B5:$E5)=0, "", $F5>$B$17*$B$20, マスタ!$A$2, $F5<$B$17*$B$20, マスタ!$A$3, TRUE, "正常") -> #NAME?
A6: 5 ゲーム目 | F6: =SUM($B6:$E6) -> 0 | G6: =_xludf.IFS(COUNT($B6:$E6)=0, "", $F6>$B$17*$B$20, マスタ!$A$2, $F6<$B$17*$B$20, マスタ!$A$3, TRUE, "正常") -> #NAME?
A7: 6 ゲーム目 | F7: =SUM($B7:$E7) -> 0 | G7: =_xludf.IFS(COUNT($B7:$E7)=0, "", $F7>$B$17*$B$20, マスタ!$A$2, $F7<$B$17*$B$20, マスタ!$A$3, TRUE, "正常") -> #NAME?
A8: 7 ゲーム目 | F8: =SUM($B8:$E8) -> 0 | G8: =_xludf.IFS(COUNT($B8:$E8)=0, "", $F8>$B$17*$B$20, マスタ!$A$2, $F8<$B$17*$B$20, マスタ!$A$3, TRUE, "正常") -> #NAME?
A9: 8 ゲーム目 | F9: =SUM($B9:$E9) -> 0 | G9: =_xludf.IFS(COUNT($B9:$E9)=0, "", $F9>$B$17*$B$20, マスタ!$A$2, $F9<$B$17*$B$20, マスタ!$A$3, TRUE, "正常") -> #NAME?
A10: 9 ゲーム目 | F10: =SUM($B10:$E10) -> 0 | G10: =_xludf.IFS(COUNT($B10:$E10)=0, "", $F10>$B$17*$B$20, マスタ!$A$2, $F10<$B$17*$B$20, マスタ!$A$3, TRUE, "正常") -> #NAME?
A11: 10 ゲーム目 | F11: =SUM($B11:$E11) -> 0 | G11: =_xludf.IFS(COUNT($B11:$E11)=0, "", $F11>$B$17*$B$20, マスタ!$A$2, $F11<$B$17*$B$20, マスタ!$A$3, TRUE, "正常") -> #NAME?
A12: 合計 | B12: =SUM(B$2:B$11) -> 2000 | C12: =SUM(C$2:C$11) -> 20000 | D12: =SUM(D$2:D$11) -> 83000 | E12: =IF(COUNTA(E$1), SUM(E$2:E$11), "-") -> - | F12: =SUM($B12:$E12) -> 105000 | G12: =_xludf.IFS($F$12>$B$17*$B$20*$B$21, マスタ!$A$2, $F$12<$B$17*$B$20*$B$21, マスタ!$A$3, TRUE, "正常") -> #NAME?
A13: 増減 | B13: =B12-$B17*$B$21 -> -33000 | C13: =C12-$B17*$B$21 -> -15000 | D13: =D12-$B17*$B$21 -> 48000 | E13: =IF(COUNTA(E$1), E12-$B17*$B$21, "-") -> - | F13: =SUM($B13:$E13) -> 0 | G13: -
A14: 清算 | B14: =B$13*$B$18 -> -1650 | C14: =C$13*$B$18 -> -750 | D14: =D$13*$B$18 -> 2400 | E14: =IF(COUNTA(E$1), E$13*$B$18, "-") -> - | F14: =SUM($B14:$E14) -> 0 | G14: -
A15: 順位 | B15: =RANK(B$14, $B$14:$E$14) -> 3 | C15: =RANK(C$14, $B$14:$E$14) -> 2 | D15: =RANK(D$14, $B$14:$E$14) -> 1 | E15: =IF(COUNTA(E$1), RANK(E$14, $B$14:$E$14), "-") -> - | F15: =SUM($B15:$E15) -> 6 | G15: -
A17: 持ち点 | B17: 35000
A18: レート | B18: 0.05
A20: プレイヤー数 | B20: =COUNTA($B$1:$E$1) -> 3
A21: ゲーム数 | B21: =COUNT($B$2:$B$11) -> 1
A22: 合計点 | B22: =$B$17*$B$20*$B$21 -> 105000

Sheet 20250528
A1: プレイヤー名 | B1: だいち | C1: えいご | D1: かいと | E1: きむら | F1: 合計 | G1: 点数チェック
A2: 1 ゲーム目 | B2: 34700 | C2: -1200 | D2: 59400 | E2: 7100 | F2: =SUM($B2:$E2) -> 100000 | G2: =_xludf.IFS(COUNT($B2:$E2)=0, "", $F2>$B$17*$B$20, マスタ!$A$2, $F2<$B$17*$B$20, マスタ!$A$3, TRUE, "正常") -> #NAME?
A3: 2 ゲーム目 | B3: 34600 | C3: 34400 | D3: 34000 | E3: -3000 | F3: =SUM($B3:$E3) -> 100000 | G3: =_xludf.IFS(COUNT($B3:$E3)=0, "", $F3>$B$17*$B$20, マスタ!$A$2, $F3<$B$17*$B$20, マスタ!$A$3, TRUE, "正常") -> #NAME?
A4: 3 ゲーム目 | B4: -1000 | C4: 6200 | D4: 14100 | E4: 80700 | F4: =SUM($B4:$E4) -> 100000 | G4: =_xludf.IFS(COUNT($B4:$E4)=0, "", $F4>$B$17*$B$20, マスタ!$A$2, $F4<$B$17*$B$20, マスタ!$A$3, TRUE, "正常") -> #NAME?
A5: 4 ゲーム目 | B5: 31100 | C5: 31500 | D5: 14400 | E5: 23000 | F5: =SUM($B5:$E5) -> 100000 | G5: =_xludf.IFS(COUNT($B5:$E5)=0, "", $F5>$B$17*$B$20, マスタ!$A$2, $F5<$B$17*$B$20, マスタ!$A$3, TRUE, "正常") -> #NAME?
A6: 5 ゲーム目 | F6: =SUM($B6:$E6) -> 0 | G6: =_xludf.IFS(COUNT($B6:$E6)=0, "", $F6>$B$17*$B$20, マスタ!$A$2, $F6<$B$17*$B$20, マスタ!$A$3, TRUE, "正常") -> #NAME?
A7: 6 ゲーム目 | F7: =SUM($B7:$E7) -> 0 | G7: =_xludf.IFS(COUNT($B7:$E7)=0, "", $F7>$B$17*$B$20, マスタ!$A$2, $F7<$B$17*$B$20, マスタ!$A$3, TRUE, "正常") -> #NAME?
A8: 7 ゲーム目 | F8: =SUM($B8:$E8) -> 0 | G8: =_xludf.IFS(COUNT($B8:$E8)=0, "", $F8>$B$17*$B$20, マスタ!$A$2, $F8<$B$17*$B$20, マスタ!$A$3, TRUE, "正常") -> #NAME?
A9: 8 ゲーム目 | F9: =SUM($B9:$E9) -> 0 | G9: =_xludf.IFS(COUNT($B9:$E9)=0, "", $F9>$B$17*$B$20, マスタ!$A$2, $F9<$B$17*$B$20, マスタ!$A$3, TRUE, "正常") -> #NAME?
A10: 9 ゲーム目 | F10: =SUM($B10:$E10) -> 0 | G10: =_xludf.IFS(COUNT($B10:$E10)=0, "", $F10>$B$17*$B$20, マスタ!$A$2, $F10<$B$17*$B$20, マスタ!$A$3, TRUE, "正常") -> #NAME?
A11: 10 ゲーム目 | F11: =SUM($B11:$E11) -> 0 | G11: =_xludf.IFS(COUNT($B11:$E11)=0, "", $F11>$B$17*$B$20, マスタ!$A$2, $F11<$B$17*$B$20, マスタ!$A$3, TRUE, "正常") -> #NAME?
A12: 合計 | B12: =SUM(B$2:B$11) -> 99400 | C12: =SUM(C$2:C$11) -> 70900 | D12: =SUM(D$2:D$11) -> 121900 | E12: =IF(COUNTA(E$1), SUM(E$2:E$11), "-") -> 107800 | F12: =SUM($B12:$E12) -> 400000 | G12: =_xludf.IFS($F$12>$B$17*$B$20*$B$21, マスタ!$A$2, $F$12<$B$17*$B$20*$B$21, マスタ!$A$3, TRUE, "正常") -> #NAME?
A13: 増減 | B13: =B12-$B17*$B$21 -> -600 | C13: =C12-$B17*$B$21 -> -29100 | D13: =D12-$B17*$B$21 -> 21900 | E13: =IF(COUNTA(E$1), E12-$B17*$B$21, "-") -> 7800 | F13: =SUM($B13:$E13) -> 0 | G13: -
A14: 清算 | B14: =B$13*$B$18 -> -60 | C14: =C$13*$B$18 -> -2910 | D14: =D$13*$B$18 -> 2190 | E14: =IF(COUNTA(E$1), E$13*$B$18, "-") -> 780 | F14: =SUM($B14:$E14) -> 0 | G14: -
A15: 順位 | B15: =RANK(B$14, $B$14:$E$14) -> 3 | C15: =RANK(C$14, $B$14:$E$14) -> 4 | D15: =RANK(D$14, $B$14:$E$14) -> 1 | E15: =IF(COUNTA(E$1), RANK(E$14, $B$14:$E$14), "-") -> 2 | F15: =SUM($B15:$E15) -> 10 | G15: -
A17: 持ち点 | B17: 25000
A18: レート | B18: 0.1
A20: プレイヤー数 | B20: =COUNTA($B$1:$E$1) -> 4
A21: ゲーム数 | B21: =COUNT($B$2:$B$11) -> 4
A22: 合計点 | B22: =$B$17*$B$20*$B$21 -> 400000

Sheet 20250531
A1: プレイヤー名 | B1: きむら | C1: だいち | D1: かいと | F1: 合計 | G1: 点数チェック
A2: 1 ゲーム目 | B2: 29000 | C2: 25000 | D2: 51000 | F2: =SUM($B2:$E2) -> 105000 | G2: =_xludf.IFS(COUNT($B2:$E2)=0, "", $F2>$B$17*$B$20, マスタ!$A$2, $F2<$B$17*$B$20, マスタ!$A$3, TRUE, "正常") -> #NAME?
A3: 2 ゲーム目 | B3: -3000 | C3: 70000 | D3: 38000 | F3: =SUM($B3:$E3) -> 105000 | G3: =_xludf.IFS(COUNT($B3:$E3)=0, "", $F3>$B$17*$B$20, マスタ!$A$2, $F3<$B$17*$B$20, マスタ!$A$3, TRUE, "正常") -> #NAME?
A4: 3 ゲーム目 | B4: 47000 | C4: 25000 | D4: 33000 | F4: =SUM($B4:$E4) -> 105000 | G4: =_xludf.IFS(COUNT($B4:$E4)=0, "", $F4>$B$17*$B$20, マスタ!$A$2, $F4<$B$17*$B$20, マスタ!$A$3, TRUE, "正常") -> #NAME?
A5: 4 ゲーム目 | B5: 20000 | C5: 69000 | D5: 16000 | F5: =SUM($B5:$E5) -> 105000 | G5: =_xludf.IFS(COUNT($B5:$E5)=0, "", $F5>$B$17*$B$20, マスタ!$A$2, $F5<$B$17*$B$20, マスタ!$A$3, TRUE, "正常") -> #NAME?
A6: 5 ゲーム目 | B6: 12000 | C6: 58000 | D6: 35000 | F6: =SUM($B6:$E6) -> 105000 | G6: =_xludf.IFS(COUNT($B6:$E6)=0, "", $F6>$B$17*$B$20, マスタ!$A$2, $F6<$B$17*$B$20, マスタ!$A$3, TRUE, "正常") -> #NAME?
A7: 6 ゲーム目 | F7: =SUM($B7:$E7) -> 0 | G7: =_xludf.IFS(COUNT($B7:$E7)=0, "", $F7>$B$17*$B$20, マスタ!$A$2, $F7<$B$17*$B$20, マスタ!$A$3, TRUE, "正常") -> #NAME?
A8: 7 ゲーム目 | F8: =SUM($B8:$E8) -> 0 | G8: =_xludf.IFS(COUNT($B8:$E8)=0, "", $F8>$B$17*$B$20, マスタ!$A$2, $F8<$B$17*$B$20, マスタ!$A$3, TRUE, "正常") -> #NAME?
A9: 8 ゲーム目 | F9: =SUM($B9:$E9) -> 0 | G9: =_xludf.IFS(COUNT($B9:$E9)=0, "", $F9>$B$17*$B$20, マスタ!$A$2, $F9<$B$17*$B$20, マスタ!$A$3, TRUE, "正常") -> #NAME?
A10: 9 ゲーム目 | F10: =SUM($B10:$E10) -> 0 | G10: =_xludf.IFS(COUNT($B10:$E10)=0, "", $F10>$B$17*$B$20, マスタ!$A$2, $F10<$B$17*$B$20, マスタ!$A$3, TRUE, "正常") -> #NAME?
A11: 10 ゲーム目 | F11: =SUM($B11:$E11) -> 0 | G11: =_xludf.IFS(COUNT($B11:$E11)=0, "", $F11>$B$17*$B$20, マスタ!$A$2, $F11<$B$17*$B$20, マスタ!$A$3, TRUE, "正常") -> #NAME?
A12: 合計 | B12: =SUM(B$2:B$11) -> 105000 | C12: =SUM(C$2:C$11) -> 247000 | D12: =SUM(D$2:D$11) -> 173000 | E12: =IF(COUNTA(E$1), SUM(E$2:E$11), "-") -> - | F12: =SUM($B12:$E12) -> 525000 | G12: =_xludf.IFS($F$12>$B$17*$B$20*$B$21, マスタ!$A$2, $F$12<$B$17*$B$20*$B$21, マスタ!$A$3, TRUE, "正常") -> #NAME?
A13: 増減 | B13: =B12-$B17*$B$21 -> -70000 | C13: =C12-$B17*$B$21 -> 72000 | D13: =D12-$B17*$B$21 -> -2000 | E13: =IF(COUNTA(E$1), E12-$B17*$B$21, "-") -> - | F13: =SUM($B13:$E13) -> 0 | G13: -
A14: 清算 | B14: =B$13*$B$18 -> -7000 | C14: =C$13*$B$18 -> 7200 | D14: =D$13*$B$18 -> -200 | E14: =IF(COUNTA(E$1), E$13*$B$18, "-") -> - | F14: =SUM($B14:$E14) -> 0 | G14: -
A15: 順位 | B15: =RANK(B$14, $B$14:$E$14) -> 3 | C15: =RANK(C$14, $B$14:$E$14) -> 1 | D15: =RANK(D$14, $B$14:$E$14) -> 2 | E15: =IF(COUNTA(E$1), RANK(E$14, $B$14:$E$14), "-") -> - | F15: =SUM($B15:$E15) -> 6 | G15: -
A17: 持ち点 | B17: 35000
A18: レート | B18: 0.1
A20: プレイヤー数 | B20: =COUNTA($B$1:$E$1) -> 3
A21: ゲーム数 | B21: =COUNT($B$2:$B$11) -> 5
A22: 合計点 | B22: =$B$17*$B$20*$B$21 -> 525000

Sheet 20250602
A1: プレイヤー名 | B1: きむら | C1: だいち | D1: かいと | E1: えいご | F1: 合計 | G1: 点数チェック
A2: 1 ゲーム目 | B2: 18000 | C2: 26000 | D2: 40000 | E2: 16000 | F2: =SUM($B2:$E2) -> 100000 | G2: =_xludf.IFS(COUNT($B2:$E2)=0, "", $F2>$B$17*$B$20, マスタ!$A$2, $F2<$B$17*$B$20, マスタ!$A$3, TRUE, "正常") -> #NAME?
A3: 2 ゲーム目 | B3: 24000 | C3: 22000 | D3: 22000 | E3: 32000 | F3: =SUM($B3:$E3) -> 100000 | G3: =_xludf.IFS(COUNT($B3:$E3)=0, "", $F3>$B$17*$B$20, マスタ!$A$2, $F3<$B$17*$B$20, マスタ!$A$3, TRUE, "正常") -> #NAME?
A4: 3 ゲーム目 | F4: =SUM($B4:$E4) -> 0 | G4: =_xludf.IFS(COUNT($B4:$E4)=0, "", $F4>$B$17*$B$20, マスタ!$A$2, $F4<$B$17*$B$20, マスタ!$A$3, TRUE, "正常") -> #NAME?
A5: 4 ゲーム目 | F5: =SUM($B5:$E5) -> 0 | G5: =_xludf.IFS(COUNT($B5:$E5)=0, "", $F5>$B$17*$B$20, マスタ!$A$2, $F5<$B$17*$B$20, マスタ!$A$3, TRUE, "正常") -> #NAME?
A6: 5 ゲーム目 | F6: =SUM($B6:$E6) -> 0 | G6: =_xludf.IFS(COUNT($B6:$E6)=0, "", $F6>$B$17*$B$20, マスタ!$A$2, $F6<$B$17*$B$20, マスタ!$A$3, TRUE, "正常") -> #NAME?
A7: 6 ゲーム目 | F7: =SUM($B7:$E7) -> 0 | G7: =_xludf.IFS(COUNT($B7:$E7)=0, "", $F7>$B$17*$B$20, マスタ!$A$2, $F7<$B$17*$B$20, マスタ!$A$3, TRUE, "正常") -> #NAME?
A8: 7 ゲーム目 | F8: =SUM($B8:$E8) -> 0 | G8: =_xludf.IFS(COUNT($B8:$E8)=0, "", $F8>$B$17*$B$20, マスタ!$A$2, $F8<$B$17*$B$20, マスタ!$A$3, TRUE, "正常") -> #NAME?
A9: 8 ゲーム目 | F9: =SUM($B9:$E9) -> 0 | G9: =_xludf.IFS(COUNT($B9:$E9)=0, "", $F9>$B$17*$B$20, マスタ!$A$2, $F9<$B$17*$B$20, マスタ!$A$3, TRUE, "正常") -> #NAME?
A10: 9 ゲーム目 | F10: =SUM($B10:$E10) -> 0 | G10: =_xludf.IFS(COUNT($B10:$E10)=0, "", $F10>$B$17*$B$20, マスタ!$A$2, $F10<$B$17*$B$20, マスタ!$A$3, TRUE, "正常") -> #NAME?
A11: 10 ゲーム目 | F11: =SUM($B11:$E11) -> 0 | G11: =_xludf.IFS(COUNT($B11:$E11)=0, "", $F11>$B$17*$B$20, マスタ!$A$2, $F11<$B$17*$B$20, マスタ!$A$3, TRUE, "正常") -> #NAME?
A12: 合計 | B12: =SUM(B$2:B$11) -> 42000 | C12: =SUM(C$2:C$11) -> 48000 | D12: =SUM(D$2:D$11) -> 62000 | E12: =IF(COUNTA(E$1), SUM(E$2:E$11), "-") -> 48000 | F12: =SUM($B12:$E12) -> 200000 | G12: =_xludf.IFS($F$12>$B$17*$B$20*$B$21, マスタ!$A$2, $F$12<$B$17*$B$20*$B$21, マスタ!$A$3, TRUE, "正常") -> #NAME?
A13: 増減 | B13: =B12-$B17*$B$21 -> -8000 | C13: =C12-$B17*$B$21 -> -2000 | D13: =D12-$B17*$B$21 -> 12000 | E13: =IF(COUNTA(E$1), E12-$B17*$B$21, "-") -> -2000 | F13: =SUM($B13:$E13) -> 0 | G13: -
A14: 清算 | B14: =B$13*$B$18 -> -800 | C14: =C$13*$B$18 -> -200 | D14: =D$13*$B$18 -> 1200 | E14: =IF(COUNTA(E$1), E$13*$B$18, "-") -> -200 | F14: =SUM($B14:$E14) -> 0 | G14: -
A15: 順位 | B15: =RANK(B$14, $B$14:$E$14) -> 4 | C15: =RANK(C$14, $B$14:$E$14) -> 2 | D15: =RANK(D$14, $B$14:$E$14) -> 1 | E15: =IF(COUNTA(E$1), RANK(E$14, $B$14:$E$14), "-") -> 2 | F15: =SUM($B15:$E15) -> 9 | G15: -
A17: 持ち点 | B17: 25000
A18: レート | B18: 0.1
A20: プレイヤー数 | B20: =COUNTA($B$1:$E$1) -> 4
A21: ゲーム数 | B21: =COUNT($B$2:$B$11) -> 2
A22: 合計点 | B22: =$B$17*$B$20*$B$21 -> 200000

Sheet 20250604
A1: プレイヤー名 | B1: えいご | C1: きむら | D1: かいと | E1: だいち | F1: 合計 | G1: 点数チェック
A2: 1 ゲーム目 | B2: 18400 | C2: 19700 | D2: 21400 | E2: 40500 | F2: =SUM($B2:$E2) -> 100000 | G2: =_xludf.IFS(COUNT($B2:$E2)=0, "", $F2>$B$17*$B$20, マスタ!$A$2, $F2<$B$17*$B$20, マスタ!$A$3, TRUE, "正常") -> #NAME?
A3: 2 ゲーム目 | B3: -2100 | C3: 43100 | D3: 19800 | E3: 39200 | F3: =SUM($B3:$E3) -> 100000 | G3: =_xludf.IFS(COUNT($B3:$E3)=0, "", $F3>$B$17*$B$20, マスタ!$A$2, $F3<$B$17*$B$20, マスタ!$A$3, TRUE, "正常") -> #NAME?
A4: 3 ゲーム目 | F4: =SUM($B4:$E4) -> 0 | G4: =_xludf.IFS(COUNT($B4:$E4)=0, "", $F4>$B$17*$B$20, マスタ!$A$2, $F4<$B$17*$B$20, マスタ!$A$3, TRUE, "正常") -> #NAME?
A5: 4 ゲーム目 | F5: =SUM($B5:$E5) -> 0 | G5: =_xludf.IFS(COUNT($B5:$E5)=0, "", $F5>$B$17*$B$20, マスタ!$A$2, $F5<$B$17*$B$20, マスタ!$A$3, TRUE, "正常") -> #NAME?
A6: 5 ゲーム目 | F6: =SUM($B6:$E6) -> 0 | G6: =_xludf.IFS(COUNT($B6:$E6)=0, "", $F6>$B$17*$B$20, マスタ!$A$2, $F6<$B$17*$B$20, マスタ!$A$3, TRUE, "正常") -> #NAME?
A7: 6 ゲーム目 | F7: =SUM($B7:$E7) -> 0 | G7: =_xludf.IFS(COUNT($B7:$E7)=0, "", $F7>$B$17*$B$20, マスタ!$A$2, $F7<$B$17*$B$20, マスタ!$A$3, TRUE, "正常") -> #NAME?
A8: 7 ゲーム目 | F8: =SUM($B8:$E8) -> 0 | G8: =_xludf.IFS(COUNT($B8:$E8)=0, "", $F8>$B$17*$B$20, マスタ!$A$2, $F8<$B$17*$B$20, マスタ!$A$3, TRUE, "正常") -> #NAME?
A9: 8 ゲーム目 | F9: =SUM($B9:$E9) -> 0 | G9: =_xludf.IFS(COUNT($B9:$E9)=0, "", $F9>$B$17*$B$20, マスタ!$A$2, $F9<$B$17*$B$20, マスタ!$A$3, TRUE, "正常") -> #NAME?
A10: 9 ゲーム目 | F10: =SUM($B10:$E10) -> 0 | G10: =_xludf.IFS(COUNT($B10:$E10)=0, "", $F10>$B$17*$B$20, マスタ!$A$2, $F10<$B$17*$B$20, マスタ!$A$3, TRUE, "正常") -> #NAME?
A11: 10 ゲーム目 | F11: =SUM($B11:$E11) -> 0 | G11: =_xludf.IFS(COUNT($B11:$E11)=0, "", $F11>$B$17*$B$20, マスタ!$A$2, $F11<$B$17*$B$20, マスタ!$A$3, TRUE, "正常") -> #NAME?
A12: 合計 | B12: =SUM(B$2:B$11) -> 16300 | C12: =SUM(C$2:C$11) -> 62800 | D12: =SUM(D$2:D$11) -> 41200 | E12: =IF(COUNTA(E$1), SUM(E$2:E$11), "-") -> 79700 | F12: =SUM($B12:$E12) -> 200000 | G12: =_xludf.IFS($F$12>$B$17*$B$20*$B$21, マスタ!$A$2, $F$12<$B$17*$B$20*$B$21, マスタ!$A$3, TRUE, "正常") -> #NAME?
A13: 増減 | B13: =B12-$B17*$B$21 -> -33700 | C13: =C12-$B17*$B$21 -> 12800 | D13: =D12-$B17*$B$21 -> -8800 | E13: =IF(COUNTA(E$1), E12-$B17*$B$21, "-") -> 29700 | F13: =SUM($B13:$E13) -> 0 | G13: -
A14: 清算 | B14: =B$13*$B$18 -> -3370 | C14: =C$13*$B$18 -> 1280 | D14: =D$13*$B$18 -> -880 | E14: =IF(COUNTA(E$1), E$13*$B$18, "-") -> 2970 | F14: =SUM($B14:$E14) -> 0 | G14: -
A15: 順位 | B15: =RANK(B$14, $B$14:$E$14) -> 4 | C15: =RANK(C$14, $B$14:$E$14) -> 2 | D15: =RANK(D$14, $B$14:$E$14) -> 3 | E15: =IF(COUNTA(E$1), RANK(E$14, $B$14:$E$14), "-") -> 1 | F15: =SUM($B15:$E15) -> 10 | G15: -
A17: 持ち点 | B17: 25000
A18: レート | B18: 0.1
A20: プレイヤー数 | B20: =COUNTA($B$1:$E$1) -> 4
A21: ゲーム数 | B21: =COUNT($B$2:$B$11) -> 2
A22: 合計点 | B22: =$B$17*$B$20*$B$21 -> 200000

Sheet 20250607
A1: プレイヤー名 | B1: だいち | C1: きむら | D1: かいと | F1: 合計 | G1: 点数チェック
A2: 1 ゲーム目 | B2: 72000 | C2: 35000 | D2: -2000 | F2: =SUM($B2:$E2) -> 105000 | G2: =_xludf.IFS(COUNT($B2:$E2)=0, "", $F2>$B$17*$B$20, マスタ!$A$2, $F2<$B$17*$B$20, マスタ!$A$3, TRUE, "正常") -> #NAME?
A3: 2 ゲーム目 | B3: 7000 | C3: 88000 | D3: 10000 | F3: =SUM($B3:$E3) -> 105000 | G3: =_xludf.IFS(COUNT($B3:$E3)=0, "", $F3>$B$17*$B$20, マスタ!$A$2, $F3<$B$17*$B$20, マスタ!$A$3, TRUE, "正常") -> #NAME?
A4: 3 ゲーム目 | B4: 25000 | C4: 26000 | D4: 54000 | F4: =SUM($B4:$E4) -> 105000 | G4: =_xludf.IFS(COUNT($B4:$E4)=0, "", $F4>$B$17*$B$20, マスタ!$A$2, $F4<$B$17*$B$20, マスタ!$A$3, TRUE, "正常") -> #NAME?
A5: 4 ゲーム目 | B5: 50000 | C5: 29000 | D5: 26000 | F5: =SUM($B5:$E5) -> 105000 | G5: =_xludf.IFS(COUNT($B5:$E5)=0, "", $F5>$B$17*$B$20, マスタ!$A$2, $F5<$B$17*$B$20, マスタ!$A$3, TRUE, "正常") -> #NAME?
A6: 5 ゲーム目 | B6: 43000 | C6: 28000 | D6: 34000 | F6: =SUM($B6:$E6) -> 105000 | G6: =_xludf.IFS(COUNT($B6:$E6)=0, "", $F6>$B$17*$B$20, マスタ!$A$2, $F6<$B$17*$B$20, マスタ!$A$3, TRUE, "正常") -> #NAME?
A7: 6 ゲーム目 | B7: 44000 | C7: 28000 | D7: 33000 | F7: =SUM($B7:$E7) -> 105000 | G7: =_xludf.IFS(COUNT($B7:$E7)=0, "", $F7>$B$17*$B$20, マスタ!$A$2, $F7<$B$17*$B$20, マスタ!$A$3, TRUE, "正常") -> #NAME?
A8: 7 ゲーム目 | B8: 4000 | C8: 63000 | D8: 38000 | F8: =SUM($B8:$E8) -> 105000 | G8: =_xludf.IFS(COUNT($B8:$E8)=0, "", $F8>$B$17*$B$20, マスタ!$A$2, $F8<$B$17*$B$20, マスタ!$A$3, TRUE, "正常") -> #NAME?
A9: 8 ゲーム目 | B9: 46000 | C9: 25000 | D9: 34000 | F9: =SUM($B9:$E9) -> 105000 | G9: =_xludf.IFS(COUNT($B9:$E9)=0, "", $F9>$B$17*$B$20, マスタ!$A$2, $F9<$B$17*$B$20, マスタ!$A$3, TRUE, "正常") -> #NAME?
A10: 9 ゲーム目 | F10: =SUM($B10:$E10) -> 0 | G10: =_xludf.IFS(COUNT($B10:$E10)=0, "", $F10>$B$17*$B$20, マスタ!$A$2, $F10<$B$17*$B$20, マスタ!$A$3, TRUE, "正常") -> #NAME?
A11: 10 ゲーム目 | F11: =SUM($B11:$E11) -> 0 | G11: =_xludf.IFS(COUNT($B11:$E11)=0, "", $F11>$B$17*$B$20, マスタ!$A$2, $F11<$B$17*$B$20, マスタ!$A$3, TRUE, "正常") -> #NAME?
A12: 合計 | B12: =SUM(B$2:B$11) -> 291000 | C12: =SUM(C$2:C$11) -> 322000 | D12: =SUM(D$2:D$11) -> 227000 | E12: =IF(COUNTA(E$1), SUM(E$2:E$11), "-") -> - | F12: =SUM($B12:$E12) -> 840000 | G12: =_xludf.IFS($F$12>$B$17*$B$20*$B$21, マスタ!$A$2, $F$12<$B$17*$B$20*$B$21, マスタ!$A$3, TRUE, "正常") -> #NAME?
A13: 増減 | B13: =B12-$B17*$B$21 -> 11000 | C13: =C12-$B17*$B$21 -> 42000 | D13: =D12-$B17*$B$21 -> -53000 | E13: =IF(COUNTA(E$1), E12-$B17*$B$21, "-") -> - | F13: =SUM($B13:$E13) -> 0 | G13: -
A14: 清算 | B14: =B$13*$B$18 -> 1100 | C14: =C$13*$B$18 -> 4200 | D14: =D$13*$B$18 -> -5300 | E14: =IF(COUNTA(E$1), E$13*$B$18, "-") -> - | F14: =SUM($B14:$E14) -> 0 | G14: -
A15: 順位 | B15: =RANK(B$14, $B$14:$E$14) -> 2 | C15: =RANK(C$14, $B$14:$E$14) -> 1 | D15: =RANK(D$14, $B$14:$E$14) -> 3 | E15: =IF(COUNTA(E$1), RANK(E$14, $B$14:$E$14), "-") -> - | F15: =SUM($B15:$E15) -> 6 | G15: -
A17: 持ち点 | B17: 35000
A18: レート | B18: 0.1
A20: プレイヤー数 | B20: =COUNTA($B$1:$E$1) -> 3
A21: ゲーム数 | B21: =COUNT($B$2:$B$11) -> 8
A22: 合計点 | B22: =$B$17*$B$20*$B$21 -> 840000

Sheet 20250615
A1: プレイヤー名 | B1: えいご | C1: かいと | D1: きむら | E1: だいち | F1: 合計 | G1: 点数チェック
A2: 1 ゲーム目 | B2: 28000 | C2: 31000 | D2: 40000 | E2: 1000 | F2: =SUM($B2:$E2) -> 100000 | G2: =_xludf.IFS(COUNT($B2:$E2)=0, "", $F2>$B$17*$B$20, マスタ!$A$2, $F2<$B$17*$B$20, マスタ!$A$3, TRUE, "正常") -> #NAME?
A3: 2 ゲーム目 | F3: =SUM($B3:$E3) -> 0 | G3: =_xludf.IFS(COUNT($B3:$E3)=0, "", $F3>$B$17*$B$20, マスタ!$A$2, $F3<$B$17*$B$20, マスタ!$A$3, TRUE, "正常") -> #NAME?
A4: 3 ゲーム目 | F4: =SUM($B4:$E4) -> 0 | G4: =_xludf.IFS(COUNT($B4:$E4)=0, "", $F4>$B$17*$B$20, マスタ!$A$2, $F4<$B$17*$B$20, マスタ!$A$3, TRUE, "正常") -> #NAME?
A5: 4 ゲーム目 | F5: =SUM($B5:$E5) -> 0 | G5: =_xludf.IFS(COUNT($B5:$E5)=0, "", $F5>$B$17*$B$20, マスタ!$A$2, $F5<$B$17*$B$20, マスタ!$A$3, TRUE, "正常") -> #NAME?
A6: 5 ゲーム目 | F6: =SUM($B6:$E6) -> 0 | G6: =_xludf.IFS(COUNT($B6:$E6)=0, "", $F6>$B$17*$B$20, マスタ!$A$2, $F6<$B$17*$B$20, マスタ!$A$3, TRUE, "正常") -> #NAME?
A7: 6 ゲーム目 | F7: =SUM($B7:$E7) -> 0 | G7: =_xludf.IFS(COUNT($B7:$E7)=0, "", $F7>$B$17*$B$20, マスタ!$A$2, $F7<$B$17*$B$20, マスタ!$A$3, TRUE, "正常") -> #NAME?
A8: 7 ゲーム目 | F8: =SUM($B8:$E8) -> 0 | G8: =_xludf.IFS(COUNT($B8:$E8)=0, "", $F8>$B$17*$B$20, マスタ!$A$2, $F8<$B$17*$B$20, マスタ!$A$3, TRUE, "正常") -> #NAME?
A9: 8 ゲーム目 | F9: =SUM($B9:$E9) -> 0 | G9: =_xludf.IFS(COUNT($B9:$E9)=0, "", $F9>$B$17*$B$20, マスタ!$A$2, $F9<$B$17*$B$20, マスタ!$A$3, TRUE, "正常") -> #NAME?
A10: 9 ゲーム目 | F10: =SUM($B10:$E10) -> 0 | G10: =_xludf.IFS(COUNT($B10:$E10)=0, "", $F10>$B$17*$B$20, マスタ!$A$2, $F10<$B$17*$B$20, マスタ!$A$3, TRUE, "正常") -> #NAME?
A11: 10 ゲーム目 | F11: =SUM($B11:$E11) -> 0 | G11: =_xludf.IFS(COUNT($B11:$E11)=0, "", $F11>$B$17*$B$20, マスタ!$A$2, $F11<$B$17*$B$20, マスタ!$A$3, TRUE, "正常") -> #NAME?
A12: 合計 | B12: =SUM(B$2:B$11) -> 28000 | C12: =SUM(C$2:C$11) -> 31000 | D12: =SUM(D$2:D$11) -> 40000 | E12: =IF(COUNTA(E$1), SUM(E$2:E$11), "-") -> 1000 | F12: =SUM($B12:$E12) -> 100000 | G12: =_xludf.IFS($F$12>$B$17*$B$20*$B$21, マスタ!$A$2, $F$12<$B$17*$B$20*$B$21, マスタ!$A$3, TRUE, "正常") -> #NAME?
A13: 増減 | B13: =B12-$B17*$B$21 -> 3000 | C13: =C12-$B17*$B$21 -> 6000 | D13: =D12-$B17*$B$21 -> 15000 | E13: =IF(COUNTA(E$1), E12-$B17*$B$21, "-") -> -24000 | F13: =SUM($B13:$E13) -> 0 | G13: -
A14: 清算 | B14: =B$13*$B$18 -> 150 | C14: =C$13*$B$18 -> 300 | D14: =D$13*$B$18 -> 750 | E14: =IF(COUNTA(E$1), E$13*$B$18, "-") -> -1200 | F14: =SUM($B14:$E14) -> 0 | G14: -
A15: 順位 | B15: =RANK(B$14, $B$14:$E$14) -> 3 | C15: =RANK(C$14, $B$14:$E$14) -> 2 | D15: =RANK(D$14, $B$14:$E$14) -> 1 | E15: =IF(COUNTA(E$1), RANK(E$14, $B$14:$E$14), "-") -> 4 | F15: =SUM($B15:$E15) -> 10 | G15: -
A17: 持ち点 | B17: 25000
A18: レート | B18: 0.05
A20: プレイヤー数 | B20: =COUNTA($B$1:$E$1) -> 4
A21: ゲーム数 | B21: =COUNT($B$2:$B$11) -> 1
A22: 合計点 | B22: =$B$17*$B$20*$B$21 -> 100000

Sheet 20250616
A1: プレイヤー名 | B1: えいご | C1: だいち | D1: かいと | F1: 合計 | G1: 点数チェック
A2: 1 ゲーム目 | B2: -3000 | C2: 41000 | D2: 67000 | F2: =SUM($B2:$E2) -> 105000 | G2: =_xludf.IFS(COUNT($B2:$E2)=0, "", $F2>$B$17*$B$20, マスタ!$A$2, $F2<$B$17*$B$20, マスタ!$A$3, TRUE, "正常") -> #NAME?
A3: 2 ゲーム目 | B3: 14000 | C3: 50000 | D3: 41000 | F3: =SUM($B3:$E3) -> 105000 | G3: =_xludf.IFS(COUNT($B3:$E3)=0, "", $F3>$B$17*$B$20, マスタ!$A$2, $F3<$B$17*$B$20, マスタ!$A$3, TRUE, "正常") -> #NAME?
A4: 3 ゲーム目 | F4: =SUM($B4:$E4) -> 0 | G4: =_xludf.IFS(COUNT($B4:$E4)=0, "", $F4>$B$17*$B$20, マスタ!$A$2, $F4<$B$17*$B$20, マスタ!$A$3, TRUE, "正常") -> #NAME?
A5: 4 ゲーム目 | F5: =SUM($B5:$E5) -> 0 | G5: =_xludf.IFS(COUNT($B5:$E5)=0, "", $F5>$B$17*$B$20, マスタ!$A$2, $F5<$B$17*$B$20, マスタ!$A$3, TRUE, "正常") -> #NAME?
A6: 5 ゲーム目 | F6: =SUM($B6:$E6) -> 0 | G6: =_xludf.IFS(COUNT($B6:$E6)=0, "", $F6>$B$17*$B$20, マスタ!$A$2, $F6<$B$17*$B$20, マスタ!$A$3, TRUE, "正常") -> #NAME?
A7: 6 ゲーム目 | F7: =SUM($B7:$E7) -> 0 | G7: =_xludf.IFS(COUNT($B7:$E7)=0, "", $F7>$B$17*$B$20, マスタ!$A$2, $F7<$B$17*$B$20, マスタ!$A$3, TRUE, "正常") -> #NAME?
A8: 7 ゲーム目 | F8: =SUM($B8:$E8) -> 0 | G8: =_xludf.IFS(COUNT($B8:$E8)=0, "", $F8>$B$17*$B$20, マスタ!$A$2, $F8<$B$17*$B$20, マスタ!$A$3, TRUE, "正常") -> #NAME?
A9: 8 ゲーム目 | F9: =SUM($B9:$E9) -> 0 | G9: =_xludf.IFS(COUNT($B9:$E9)=0, "", $F9>$B$17*$B$20, マスタ!$A$2, $F9<$B$17*$B$20, マスタ!$A$3, TRUE, "正常") -> #NAME?
A10: 9 ゲーム目 | F10: =SUM($B10:$E10) -> 0 | G10: =_xludf.IFS(COUNT($B10:$E10)=0, "", $F10>$B$17*$B$20, マスタ!$A$2, $F10<$B$17*$B$20, マスタ!$A$3, TRUE, "正常") -> #NAME?
A11: 10 ゲーム目 | F11: =SUM($B11:$E11) -> 0 | G11: =_xludf.IFS(COUNT($B11:$E11)=0, "", $F11>$B$17*$B$20, マスタ!$A$2, $F11<$B$17*$B$20, マスタ!$A$3, TRUE, "正常") -> #NAME?
A12: 合計 | B12: =SUM(B$2:B$11) -> 11000 | C12: =SUM(C$2:C$11) -> 91000 | D12: =SUM(D$2:D$11) -> 108000 | E12: =IF(COUNTA(E$1), SUM(E$2:E$11), "-") -> - | F12: =SUM($B12:$E12) -> 210000 | G12: =_xludf.IFS($F$12>$B$17*$B$20*$B$21, マスタ!$A$2, $F$12<$B$17*$B$20*$B$21, マスタ!$A$3, TRUE, "正常") -> #NAME?
A13: 増減 | B13: =B12-$B17*$B$21 -> -59000 | C13: =C12-$B17*$B$21 -> 21000 | D13: =D12-$B17*$B$21 -> 38000 | E13: =IF(COUNTA(E$1), E12-$B17*$B$21, "-") -> - | F13: =SUM($B13:$E13) -> 0 | G13: -
A14: 清算 | B14: =B$13*$B$18 -> -2950 | C14: =C$13*$B$18 -> 1050 | D14: =D$13*$B$18 -> 1900 | E14: =IF(COUNTA(E$1), E$13*$B$18, "-") -> - | F14: =SUM($B14:$E14) -> 0 | G14: -
A15: 順位 | B15: =RANK(B$14, $B$14:$E$14) -> 3 | C15: =RANK(C$14, $B$14:$E$14) -> 2 | D15: =RANK(D$14, $B$14:$E$14) -> 1 | E15: =IF(COUNTA(E$1), RANK(E$14, $B$14:$E$14), "-") -> - | F15: =SUM($B15:$E15) -> 6 | G15: -
A17: 持ち点 | B17: 35000
A18: レート | B18: 0.05
A20: プレイヤー数 | B20: =COUNTA($B$1:$E$1) -> 3
A21: ゲーム数 | B21: =COUNT($B$2:$B$11) -> 2
A22: 合計点 | B22: =$B$17*$B$20*$B$21 -> 210000

Sheet 20250619
A1: プレイヤー名 | B1: えいご | C1: かいと | D1: きむら | E1: だいち | F1: 合計 | G1: 点数チェック
A2: 1 ゲーム目 | B2: 11100 | C2: 10300 | D2: 23700 | E2: 54900 | F2: =SUM($B2:$E2) -> 100000 | G2: =_xludf.IFS(COUNT($B2:$E2)=0, "", $F2>$B$17*$B$20, マスタ!$A$2, $F2<$B$17*$B$20, マスタ!$A$3, TRUE, "正常") -> #NAME?
A3: 2 ゲーム目 | B3: 41900 | C3: 43000 | D3: -5900 | E3: 21000 | F3: =SUM($B3:$E3) -> 100000 | G3: =_xludf.IFS(COUNT($B3:$E3)=0, "", $F3>$B$17*$B$20, マスタ!$A$2, $F3<$B$17*$B$20, マスタ!$A$3, TRUE, "正常") -> #NAME?
A4: 3 ゲーム目 | B4: 15600 | C4: 29500 | D4: 21000 | E4: 33900 | F4: =SUM($B4:$E4) -> 100000 | G4: =_xludf.IFS(COUNT($B4:$E4)=0, "", $F4>$B$17*$B$20, マスタ!$A$2, $F4<$B$17*$B$20, マスタ!$A$3, TRUE, "正常") -> #NAME?
A5: 4 ゲーム目 | B5: 7200 | C5: 57900 | D5: 18800 | E5: 16100 | F5: =SUM($B5:$E5) -> 100000 | G5: =_xludf.IFS(COUNT($B5:$E5)=0, "", $F5>$B$17*$B$20, マスタ!$A$2, $F5<$B$17*$B$20, マスタ!$A$3, TRUE, "正常") -> #NAME?
A6: 5 ゲーム目 | F6: =SUM($B6:$E6) -> 0 | G6: =_xludf.IFS(COUNT($B6:$E6)=0, "", $F6>$B$17*$B$20, マスタ!$A$2, $F6<$B$17*$B$20, マスタ!$A$3, TRUE, "正常") -> #NAME?
A7: 6 ゲーム目 | F7: =SUM($B7:$E7) -> 0 | G7: =_xludf.IFS(COUNT($B7:$E7)=0, "", $F7>$B$17*$B$20, マスタ!$A$2, $F7<$B$17*$B$20, マスタ!$A$3, TRUE, "正常") -> #NAME?
A8: 7 ゲーム目 | F8: =SUM($B8:$E8) -> 0 | G8: =_xludf.IFS(COUNT($B8:$E8)=0, "", $F8>$B$17*$B$20, マスタ!$A$2, $F8<$B$17*$B$20, マスタ!$A$3, TRUE, "正常") -> #NAME?
A9: 8 ゲーム目 | F9: =SUM($B9:$E9) -> 0 | G9: =_xludf.IFS(COUNT($B9:$E9)=0, "", $F9>$B$17*$B$20, マスタ!$A$2, $F9<$B$17*$B$20, マスタ!$A$3, TRUE, "正常") -> #NAME?
A10: 9 ゲーム目 | F10: =SUM($B10:$E10) -> 0 | G10: =_xludf.IFS(COUNT($B10:$E10)=0, "", $F10>$B$17*$B$20, マスタ!$A$2, $F10<$B$17*$B$20, マスタ!$A$3, TRUE, "正常") -> #NAME?
A11: 10 ゲーム目 | F11: =SUM($B11:$E11) -> 0 | G11: =_xludf.IFS(COUNT($B11:$E11)=0, "", $F11>$B$17*$B$20, マスタ!$A$2, $F11<$B$17*$B$20, マスタ!$A$3, TRUE, "正常") -> #NAME?
A12: 合計 | B12: =SUM(B$2:B$11) -> 75800 | C12: =SUM(C$2:C$11) -> 140700 | D12: =SUM(D$2:D$11) -> 57600 | E12: =IF(COUNTA(E$1), SUM(E$2:E$11), "-") -> 125900 | F12: =SUM($B12:$E12) -> 400000 | G12: =_xludf.IFS($F$12>$B$17*$B$20*$B$21, マスタ!$A$2, $F$12<$B$17*$B$20*$B$21, マスタ!$A$3, TRUE, "正常") -> #NAME?
A13: 増減 | B13: =B12-$B17*$B$21 -> -24200 | C13: =C12-$B17*$B$21 -> 40700 | D13: =D12-$B17*$B$21 -> -42400 | E13: =IF(COUNTA(E$1), E12-$B17*$B$21, "-") -> 25900 | F13: =SUM($B13:$E13) -> 0 | G13: -
A14: 清算 | B14: =B$13*$B$18 -> -2420 | C14: =C$13*$B$18 -> 4070 | D14: =D$13*$B$18 -> -4240 | E14: =IF(COUNTA(E$1), E$13*$B$18, "-") -> 2590 | F14: =SUM($B14:$E14) -> 0 | G14: -
A15: 順位 | B15: =RANK(B$14, $B$14:$E$14) -> 3 | C15: =RANK(C$14, $B$14:$E$14) -> 1 | D15: =RANK(D$14, $B$14:$E$14) -> 4 | E15: =IF(COUNTA(E$1), RANK(E$14, $B$14:$E$14), "-") -> 2 | F15: =SUM($B15:$E15) -> 10 | G15: -
A17: 持ち点 | B17: 25000
A18: レート | B18: 0.1
A20: プレイヤー数 | B20: =COUNTA($B$1:$E$1) -> 4
A21: ゲーム数 | B21: =COUNT($B$2:$B$11) -> 4
A22: 合計点 | B22: =$B$17*$B$20*$B$21 -> 400000

Sheet 20250623
A1: プレイヤー名 | B1: えいご | C1: かいと | D1: だいち | F1: 合計 | G1: 点数チェック
A2: 1 ゲーム目 | B2: 47000 | C2: 7000 | D2: 51000 | F2: =SUM($B2:$E2) -> 105000 | G2: =_xludf.IFS(COUNT($B2:$E2)=0, "", $F2>$B$17*$B$20, マスタ!$A$2, $F2<$B$17*$B$20, マスタ!$A$3, TRUE, "正常") -> #NAME?
A3: 2 ゲーム目 | B3: -4000 | C3: 26000 | D3: 83000 | F3: =SUM($B3:$E3) -> 105000 | G3: =_xludf.IFS(COUNT($B3:$E3)=0, "", $F3>$B$17*$B$20, マスタ!$A$2, $F3<$B$17*$B$20, マスタ!$A$3, TRUE, "正常") -> #NAME?
A4: 3 ゲーム目 | B4: 30000 | C4: 30000 | D4: 45000 | F4: =SUM($B4:$E4) -> 105000 | G4: =_xludf.IFS(COUNT($B4:$E4)=0, "", $F4>$B$17*$B$20, マスタ!$A$2, $F4<$B$17*$B$20, マスタ!$A$3, TRUE, "正常") -> #NAME?
A5: 4 ゲーム目 | F5: =SUM($B5:$E5) -> 0 | G5: =_xludf.IFS(COUNT($B5:$E5)=0, "", $F5>$B$17*$B$20, マスタ!$A$2, $F5<$B$17*$B$20, マスタ!$A$3, TRUE, "正常") -> #NAME?
A6: 5 ゲーム目 | F6: =SUM($B6:$E6) -> 0 | G6: =_xludf.IFS(COUNT($B6:$E6)=0, "", $F6>$B$17*$B$20, マスタ!$A$2, $F6<$B$17*$B$20, マスタ!$A$3, TRUE, "正常") -> #NAME?
A7: 6 ゲーム目 | F7: =SUM($B7:$E7) -> 0 | G7: =_xludf.IFS(COUNT($B7:$E7)=0, "", $F7>$B$17*$B$20, マスタ!$A$2, $F7<$B$17*$B$20, マスタ!$A$3, TRUE, "正常") -> #NAME?
A8: 7 ゲーム目 | F8: =SUM($B8:$E8) -> 0 | G8: =_xludf.IFS(COUNT($B8:$E8)=0, "", $F8>$B$17*$B$20, マスタ!$A$2, $F8<$B$17*$B$20, マスタ!$A$3, TRUE, "正常") -> #NAME?
A9: 8 ゲーム目 | F9: =SUM($B9:$E9) -> 0 | G9: =_xludf.IFS(COUNT($B9:$E9)=0, "", $F9>$B$17*$B$20, マスタ!$A$2, $F9<$B$17*$B$20, マスタ!$A$3, TRUE, "正常") -> #NAME?
A10: 9 ゲーム目 | F10: =SUM($B10:$E10) -> 0 | G10: =_xludf.IFS(COUNT($B10:$E10)=0, "", $F10>$B$17*$B$20, マスタ!$A$2, $F10<$B$17*$B$20, マスタ!$A$3, TRUE, "正常") -> #NAME?
A11: 10 ゲーム目 | F11: =SUM($B11:$E11) -> 0 | G11: =_xludf.IFS(COUNT($B11:$E11)=0, "", $F11>$B$17*$B$20, マスタ!$A$2, $F11<$B$17*$B$20, マスタ!$A$3, TRUE, "正常") -> #NAME?
A12: 合計 | B12: =SUM(B$2:B$11) -> 73000 | C12: =SUM(C$2:C$11) -> 63000 | D12: =SUM(D$2:D$11) -> 179000 | E12: =IF(COUNTA(E$1), SUM(E$2:E$11), "-") -> - | F12: =SUM($B12:$E12) -> 315000 | G12: =_xludf.IFS($F$12>$B$17*$B$20*$B$21, マスタ!$A$2, $F$12<$B$17*$B$20*$B$21, マスタ!$A$3, TRUE, "正常") -> #NAME?
A13: 増減 | B13: =B12-$B17*$B$21 -> -32000 | C13: =C12-$B17*$B$21 -> -42000 | D13: =D12-$B17*$B$21 -> 74000 | E13: =IF(COUNTA(E$1), E12-$B17*$B$21, "-") -> - | F13: =SUM($B13:$E13) -> 0 | G13: -
A14: 清算 | B14: =B$13*$B$18 -> -1600 | C14: =C$13*$B$18 -> -2100 | D14: =D$13*$B$18 -> 3700 | E14: =IF(COUNTA(E$1), E$13*$B$18, "-") -> - | F14: =SUM($B14:$E14) -> 0 | G14: -
A15: 順位 | B15: =RANK(B$14, $B$14:$E$14) -> 2 | C15: =RANK(C$14, $B$14:$E$14) -> 3 | D15: =RANK(D$14, $B$14:$E$14) -> 1 | E15: =IF(COUNTA(E$1), RANK(E$14, $B$14:$E$14), "-") -> - | F15: =SUM($B15:$E15) -> 6 | G15: -
A17: 持ち点 | B17: 35000
A18: レート | B18: 0.05
A20: プレイヤー数 | B20: =COUNTA($B$1:$E$1) -> 3
A21: ゲーム数 | B21: =COUNT($B$2:$B$11) -> 3
A22: 合計点 | B22: =$B$17*$B$20*$B$21 -> 315000

Sheet 20250625三麻
A1: プレイヤー名 | B1: きむら | C1: かいと | D1: だいち | F1: 合計 | G1: 点数チェック
A2: 1 ゲーム目 | B2: 94000 | C2: 19000 | D2: -8000 | F2: =SUM($B2:$E2) -> 105000 | G2: =_xludf.IFS(COUNT($B2:$E2)=0, "", $F2>$B$17*$B$20, マスタ!$A$2, $F2<$B$17*$B$20, マスタ!$A$3, TRUE, "正常") -> #NAME?
A3: 2 ゲーム目 | F3: =SUM($B3:$E3) -> 0 | G3: =_xludf.IFS(COUNT($B3:$E3)=0, "", $F3>$B$17*$B$20, マスタ!$A$2, $F3<$B$17*$B$20, マスタ!$A$3, TRUE, "正常") -> #NAME?
A4: 3 ゲーム目 | F4: =SUM($B4:$E4) -> 0 | G4: =_xludf.IFS(COUNT($B4:$E4)=0, "", $F4>$B$17*$B$20, マスタ!$A$2, $F4<$B$17*$B$20, マスタ!$A$3, TRUE, "正常") -> #NAME?
A5: 4 ゲーム目 | D5: ちんちん | F5: =SUM($B5:$E5) -> 0 | G5: =_xludf.IFS(COUNT($B5:$E5)=0, "", $F5>$B$17*$B$20, マスタ!$A$2, $F5<$B$17*$B$20, マスタ!$A$3, TRUE, "正常") -> #NAME?
A6: 5 ゲーム目 | F6: =SUM($B6:$E6) -> 0 | G6: =_xludf.IFS(COUNT($B6:$E6)=0, "", $F6>$B$17*$B$20, マスタ!$A$2, $F6<$B$17*$B$20, マスタ!$A$3, TRUE, "正常") -> #NAME?
A7: 6 ゲーム目 | F7: =SUM($B7:$E7) -> 0 | G7: =_xludf.IFS(COUNT($B7:$E7)=0, "", $F7>$B$17*$B$20, マスタ!$A$2, $F7<$B$17*$B$20, マスタ!$A$3, TRUE, "正常") -> #NAME?
A8: 7 ゲーム目 | F8: =SUM($B8:$E8) -> 0 | G8: =_xludf.IFS(COUNT($B8:$E8)=0, "", $F8>$B$17*$B$20, マスタ!$A$2, $F8<$B$17*$B$20, マスタ!$A$3, TRUE, "正常") -> #NAME?
A9: 8 ゲーム目 | F9: =SUM($B9:$E9) -> 0 | G9: =_xludf.IFS(COUNT($B9:$E9)=0, "", $F9>$B$17*$B$20, マスタ!$A$2, $F9<$B$17*$B$20, マスタ!$A$3, TRUE, "正常") -> #NAME?
A10: 9 ゲーム目 | F10: =SUM($B10:$E10) -> 0 | G10: =_xludf.IFS(COUNT($B10:$E10)=0, "", $F10>$B$17*$B$20, マスタ!$A$2, $F10<$B$17*$B$20, マスタ!$A$3, TRUE, "正常") -> #NAME?
A11: 10 ゲーム目 | F11: =SUM($B11:$E11) -> 0 | G11: =_xludf.IFS(COUNT($B11:$E11)=0, "", $F11>$B$17*$B$20, マスタ!$A$2, $F11<$B$17*$B$20, マスタ!$A$3, TRUE, "正常") -> #NAME?
A12: 合計 | B12: =SUM(B$2:B$11) -> 94000 | C12: =SUM(C$2:C$11) -> 19000 | D12: =SUM(D$2:D$11) -> -8000 | E12: =IF(COUNTA(E$1), SUM(E$2:E$11), "-") -> - | F12: =SUM($B12:$E12) -> 105000 | G12: =_xludf.IFS($F$12>$B$17*$B$20*$B$21, マスタ!$A$2, $F$12<$B$17*$B$20*$B$21, マスタ!$A$3, TRUE, "正常") -> #NAME?
A13: 増減 | B13: =B12-$B17*$B$21 -> 59000 | C13: =C12-$B17*$B$21 -> -16000 | D13: =D12-$B17*$B$21 -> -43000 | E13: =IF(COUNTA(E$1), E12-$B17*$B$21, "-") -> - | F13: =SUM($B13:$E13) -> 0 | G13: -
A14: 清算 | B14: =B$13*$B$18 -> 2950 | C14: =C$13*$B$18 -> -800 | D14: =D$13*$B$18 -> -2150 | E14: =IF(COUNTA(E$1), E$13*$B$18, "-") -> - | F14: =SUM($B14:$E14) -> 0 | G14: -
A15: 順位 | B15: =RANK(B$14, $B$14:$E$14) -> 1 | C15: =RANK(C$14, $B$14:$E$14) -> 2 | D15: =RANK(D$14, $B$14:$E$14) -> 3 | E15: =IF(COUNTA(E$1), RANK(E$14, $B$14:$E$14), "-") -> - | F15: =SUM($B15:$E15) -> 6 | G15: -
A17: 持ち点 | B17: 35000
A18: レート | B18: 0.05
A20: プレイヤー数 | B20: =COUNTA($B$1:$E$1) -> 3
A21: ゲーム数 | B21: =COUNT($B$2:$B$11) -> 1
A22: 合計点 | B22: =$B$17*$B$20*$B$21 -> 105000

Sheet 20250625四麻
A1: プレイヤー名 | B1: きむら | C1: かいと | D1: だいち | E1: えいご | F1: 合計 | G1: 点数チェック
A2: 1 ゲーム目 | B2: 22900 | C2: 18300 | D2: 40800 | E2: 18000 | F2: =SUM($B2:$E2) -> 100000 | G2: =_xludf.IFS(COUNT($B2:$E2)=0, "", $F2>$B$17*$B$20, マスタ!$A$2, $F2<$B$17*$B$20, マスタ!$A$3, TRUE, "正常") -> #NAME?
A3: 2 ゲーム目 | B3: 11300 | C3: 31800 | D3: 18300 | E3: 38600 | F3: =SUM($B3:$E3) -> 100000 | G3: =_xludf.IFS(COUNT($B3:$E3)=0, "", $F3>$B$17*$B$20, マスタ!$A$2, $F3<$B$17*$B$20, マスタ!$A$3, TRUE, "正常") -> #NAME?
A4: 3 ゲーム目 | B4: 18500 | C4: 28800 | D4: 18200 | E4: 34500 | F4: =SUM($B4:$E4) -> 100000 | G4: =_xludf.IFS(COUNT($B4:$E4)=0, "", $F4>$B$17*$B$20, マスタ!$A$2, $F4<$B$17*$B$20, マスタ!$A$3, TRUE, "正常") -> #NAME?
A5: 4 ゲーム目 | F5: =SUM($B5:$E5) -> 0 | G5: =_xludf.IFS(COUNT($B5:$E5)=0, "", $F5>$B$17*$B$20, マスタ!$A$2, $F5<$B$17*$B$20, マスタ!$A$3, TRUE, "正常") -> #NAME?
A6: 5 ゲーム目 | F6: =SUM($B6:$E6) -> 0 | G6: =_xludf.IFS(COUNT($B6:$E6)=0, "", $F6>$B$17*$B$20, マスタ!$A$2, $F6<$B$17*$B$20, マスタ!$A$3, TRUE, "正常") -> #NAME?
A7: 6 ゲーム目 | F7: =SUM($B7:$E7) -> 0 | G7: =_xludf.IFS(COUNT($B7:$E7)=0, "", $F7>$B$17*$B$20, マスタ!$A$2, $F7<$B$17*$B$20, マスタ!$A$3, TRUE, "正常") -> #NAME?
A8: 7 ゲーム目 | F8: =SUM($B8:$E8) -> 0 | G8: =_xludf.IFS(COUNT($B8:$E8)=0, "", $F8>$B$17*$B$20, マスタ!$A$2, $F8<$B$17*$B$20, マスタ!$A$3, TRUE, "正常") -> #NAME?
A9: 8 ゲーム目 | F9: =SUM($B9:$E9) -> 0 | G9: =_xludf.IFS(COUNT($B9:$E9)=0, "", $F9>$B$17*$B$20, マスタ!$A$2, $F9<$B$17*$B$20, マスタ!$A$3, TRUE, "正常") -> #NAME?
A10: 9 ゲーム目 | F10: =SUM($B10:$E10) -> 0 | G10: =_xludf.IFS(COUNT($B10:$E10)=0, "", $F10>$B$17*$B$20, マスタ!$A$2, $F10<$B$17*$B$20, マスタ!$A$3, TRUE, "正常") -> #NAME?
A11: 10 ゲーム目 | F11: =SUM($B11:$E11) -> 0 | G11: =_xludf.IFS(COUNT($B11:$E11)=0, "", $F11>$B$17*$B$20, マスタ!$A$2, $F11<$B$17*$B$20, マスタ!$A$3, TRUE, "正常") -> #NAME?
A12: 合計 | B12: =SUM(B$2:B$11) -> 52700 | C12: =SUM(C$2:C$11) -> 78900 | D12: =SUM(D$2:D$11) -> 77300 | E12: =IF(COUNTA(E$1), SUM(E$2:E$11), "-") -> 91100 | F12: =SUM($B12:$E12) -> 300000 | G12: =_xludf.IFS($F$12>$B$17*$B$20*$B$21, マスタ!$A$2, $F$12<$B$17*$B$20*$B$21, マスタ!$A$3, TRUE, "正常") -> #NAME?
A13: 増減 | B13: =B12-$B17*$B$21 -> -22300 | C13: =C12-$B17*$B$21 -> 3900 | D13: =D12-$B17*$B$21 -> 2300 | E13: =IF(COUNTA(E$1), E12-$B17*$B$21, "-") -> 16100 | F13: =SUM($B13:$E13) -> 0 | G13: -
A14: 清算 | B14: =B$13*$B$18 -> -2230 | C14: =C$13*$B$18 -> 390 | D14: =D$13*$B$18 -> 230 | E14: =IF(COUNTA(E$1), E$13*$B$18, "-") -> 1610 | F14: =SUM($B14:$E14) -> 0 | G14: -
A15: 順位 | B15: =RANK(B$14, $B$14:$E$14) -> 4 | C15: =RANK(C$14, $B$14:$E$14) -> 2 | D15: =RANK(D$14, $B$14:$E$14) -> 3 | E15: =IF(COUNTA(E$1), RANK(E$14, $B$14:$E$14), "-") -> 1 | F15: =SUM($B15:$E15) -> 10 | G15: -
A17: 持ち点 | B17: 25000
A18: レート | B18: 0.1
A20: プレイヤー数 | B20: =COUNTA($B$1:$E$1) -> 4
A21: ゲーム数 | B21: =COUNT($B$2:$B$11) -> 3
A22: 合計点 | B22: =$B$17*$B$20*$B$21 -> 300000

Sheet 20250628
A1: プレイヤー名 | B1: きむら | C1: かいと | D1: だいち | E1: えいご | F1: 合計 | G1: 点数チェック
A2: 1 ゲーム目 | B2: 26000 | C2: 30300 | D2: 14900 | E2: 28800 | F2: =SUM($B2:$E2) -> 100000 | G2: =_xludf.IFS(COUNT($B2:$E2)=0, "", $F2>$B$17*$B$20, マスタ!$A$2, $F2<$B$17*$B$20, マスタ!$A$3, TRUE, "正常") -> #NAME?
A3: 2 ゲーム目 | B3: 41700 | C3: 15800 | D3: 45000 | E3: -2500 | F3: =SUM($B3:$E3) -> 100000 | G3: =_xludf.IFS(COUNT($B3:$E3)=0, "", $F3>$B$17*$B$20, マスタ!$A$2, $F3<$B$17*$B$20, マスタ!$A$3, TRUE, "正常") -> #NAME?
A4: 3 ゲーム目 | B4: -5700 | C4: 36200 | D4: 39700 | E4: 29800 | F4: =SUM($B4:$E4) -> 100000 | G4: =_xludf.IFS(COUNT($B4:$E4)=0, "", $F4>$B$17*$B$20, マスタ!$A$2, $F4<$B$17*$B$20, マスタ!$A$3, TRUE, "正常") -> #NAME?
A5: 4 ゲーム目 | B5: 32800 | C5: 9000 | D5: 52900 | E5: 5300 | F5: =SUM($B5:$E5) -> 100000 | G5: =_xludf.IFS(COUNT($B5:$E5)=0, "", $F5>$B$17*$B$20, マスタ!$A$2, $F5<$B$17*$B$20, マスタ!$A$3, TRUE, "正常") -> #NAME?
A6: 5 ゲーム目 | B6: 11000 | C6: 36000 | D6: 29000 | E6: 24000 | F6: =SUM($B6:$E6) -> 100000 | G6: =_xludf.IFS(COUNT($B6:$E6)=0, "", $F6>$B$17*$B$20, マスタ!$A$2, $F6<$B$17*$B$20, マスタ!$A$3, TRUE, "正常") -> #NAME?
A7: 6 ゲーム目 | F7: =SUM($B7:$E7) -> 0 | G7: =_xludf.IFS(COUNT($B7:$E7)=0, "", $F7>$B$17*$B$20, マスタ!$A$2, $F7<$B$17*$B$20, マスタ!$A$3, TRUE, "正常") -> #NAME?
A8: 7 ゲーム目 | F8: =SUM($B8:$E8) -> 0 | G8: =_xludf.IFS(COUNT($B8:$E8)=0, "", $F8>$B$17*$B$20, マスタ!$A$2, $F8<$B$17*$B$20, マスタ!$A$3, TRUE, "正常") -> #NAME?
A9: 8 ゲーム目 | F9: =SUM($B9:$E9) -> 0 | G9: =_xludf.IFS(COUNT($B9:$E9)=0, "", $F9>$B$17*$B$20, マスタ!$A$2, $F9<$B$17*$B$20, マスタ!$A$3, TRUE, "正常") -> #NAME?
A10: 9 ゲーム目 | F10: =SUM($B10:$E10) -> 0 | G10: =_xludf.IFS(COUNT($B10:$E10)=0, "", $F10>$B$17*$B$20, マスタ!$A$2, $F10<$B$17*$B$20, マスタ!$A$3, TRUE, "正常") -> #NAME?
A11: 10 ゲーム目 | F11: =SUM($B11:$E11) -> 0 | G11: =_xludf.IFS(COUNT($B11:$E11)=0, "", $F11>$B$17*$B$20, マスタ!$A$2, $F11<$B$17*$B$20, マスタ!$A$3, TRUE, "正常") -> #NAME?
A12: 合計 | B12: =SUM(B$2:B$11) -> 105800 | C12: =SUM(C$2:C$11) -> 127300 | D12: =SUM(D$2:D$11) -> 181500 | E12: =IF(COUNTA(E$1), SUM(E$2:E$11), "-") -> 85400 | F12: =SUM($B12:$E12) -> 500000 | G12: =_xludf.IFS($F$12>$B$17*$B$20*$B$21, マスタ!$A$2, $F$12<$B$17*$B$20*$B$21, マスタ!$A$3, TRUE, "正常") -> #NAME?
A13: 増減 | B13: =B12-$B17*$B$21 -> -19200 | C13: =C12-$B17*$B$21 -> 2300 | D13: =D12-$B17*$B$21 -> 56500 | E13: =IF(COUNTA(E$1), E12-$B17*$B$21, "-") -> -39600 | F13: =SUM($B13:$E13) -> 0 | G13: -
A14: 清算 | B14: =B$13*$B$18 -> -1920 | C14: =C$13*$B$18 -> 230 | D14: =D$13*$B$18 -> 5650 | E14: =IF(COUNTA(E$1), E$13*$B$18, "-") -> -3960 | F14: =SUM($B14:$E14) -> 0 | G14: -
A15: 順位 | B15: =RANK(B$14, $B$14:$E$14) -> 3 | C15: =RANK(C$14, $B$14:$E$14) -> 2 | D15: =RANK(D$14, $B$14:$E$14) -> 1 | E15: =IF(COUNTA(E$1), RANK(E$14, $B$14:$E$14), "-") -> 4 | F15: =SUM($B15:$E15) -> 10 | G15: -
A17: 持ち点 | B17: 25000
A18: レート | B18: 0.1
A20: プレイヤー数 | B20: =COUNTA($B$1:$E$1) -> 4
A21: ゲーム数 | B21: =COUNT($B$2:$B$11) -> 5
A22: 合計点 | B22: =$B$17*$B$20*$B$21 -> 500000

Sheet 20250630
A1: プレイヤー名 | B1: きむら | C1: かいと | D1: えいご | F1: 合計 | G1: 点数チェック
A2: 1 ゲーム目 | B2: 44000 | C2: 51000 | D2: 10000 | F2: =SUM($B2:$E2) -> 105000 | G2: =_xludf.IFS(COUNT($B2:$E2)=0, "", $F2>$B$18*$B$21, マスタ!$A$2, $F2<$B$18*$B$21, マスタ!$A$3, TRUE, "正常") -> #NAME?
A3: 2 ゲーム目 | B3: 39000 | C3: 67000 | D3: -1000 | F3: =SUM($B3:$E3) -> 105000 | G3: =_xludf.IFS(COUNT($B3:$E3)=0, "", $F3>$B$18*$B$21, マスタ!$A$2, $F3<$B$18*$B$21, マスタ!$A$3, TRUE, "正常") -> #NAME?
A4: 3 ゲーム目 | B4: 29000 | C4: 40000 | D4: 36000 | F4: =SUM($B4:$E4) -> 105000 | G4: =_xludf.IFS(COUNT($B4:$E4)=0, "", $F4>$B$18*$B$21, マスタ!$A$2, $F4<$B$18*$B$21, マスタ!$A$3, TRUE, "正常") -> #NAME?
A5: 4 ゲーム目 | B5: -3000 | C5: 48000 | D5: 60000 | F5: =SUM($B5:$E5) -> 105000 | G5: =_xludf.IFS(COUNT($B5:$E5)=0, "", $F5>$B$18*$B$21, マスタ!$A$2, $F5<$B$18*$B$21, マスタ!$A$3, TRUE, "正常") -> #NAME?
A6: 5 ゲーム目 | B6: 25000 | C6: 55000 | D6: 25000 | F6: =SUM($B6:$E6) -> 105000 | G6: =_xludf.IFS(COUNT($B6:$E6)=0, "", $F6>$B$18*$B$21, マスタ!$A$2, $F6<$B$18*$B$21, マスタ!$A$3, TRUE, "正常") -> #NAME?
A7: 6 ゲーム目 | B7: 90000 | C7: -3000 | D7: 18000 | F7: =SUM($B7:$E7) -> 105000 | G7: =_xludf.IFS(COUNT($B7:$E7)=0, "", $F7>$B$18*$B$21, マスタ!$A$2, $F7<$B$18*$B$21, マスタ!$A$3, TRUE, "正常") -> #NAME?
A8: 7 ゲーム目 | B8: 42000 | C8: 43000 | D8: 20000 | F8: =SUM($B8:$E8) -> 105000 | G8: =_xludf.IFS(COUNT($B8:$E8)=0, "", $F8>$B$18*$B$21, マスタ!$A$2, $F8<$B$18*$B$21, マスタ!$A$3, TRUE, "正常") -> #NAME?
A9: 8 ゲーム目 | B9: -1000 | C9: 55000 | D9: 51000 | F9: =SUM($B9:$E9) -> 105000 | G9: =_xludf.IFS(COUNT($B9:$E9)=0, "", $F9>$B$18*$B$21, マスタ!$A$2, $F9<$B$18*$B$21, マスタ!$A$3, TRUE, "正常") -> #NAME?
A10: 9 ゲーム目 | B10: 67000 | C10: 27000 | D10: 11000 | F10: =SUM($B10:$E10) -> 105000 | G10: =_xludf.IFS(COUNT($B10:$E10)=0, "", $F10>$B$18*$B$21, マスタ!$A$2, $F10<$B$18*$B$21, マスタ!$A$3, TRUE, "正常") -> #NAME?
A11: 10 ゲーム目 | B11: 55000 | C11: -10000 | D11: 60000 | F11: =SUM($B11:$E11) -> 105000 | G11: =_xludf.IFS(COUNT($B11:$E11)=0, "", $F11>$B$18*$B$21, マスタ!$A$2, $F11<$B$18*$B$21, マスタ!$A$3, TRUE, "正常") -> #NAME?
A12: 11 ゲーム目 | F12: =SUM($B12:$E12) -> 0 | G12: =_xludf.IFS(COUNT($B12:$E12)=0, "", $F12>$B$18*$B$21, マスタ!$A$2, $F12<$B$18*$B$21, マスタ!$A$3, TRUE, "正常") -> #NAME?
A13: 合計 | B13: =SUM(B$2:B$11) -> 387000 | C13: =SUM(C$2:C$11) -> 373000 | D13: =SUM(D$2:D$11) -> 290000 | E13: =IF(COUNTA(E$1), SUM(E$2:E$11), "-") -> - | F13: =SUM($B13:$E13) -> 1050000 | G13: =_xludf.IFS($F$13>$B$18*$B$21*$B$22, マスタ!$A$2, $F$13<$B$18*$B$21*$B$22, マスタ!$A$3, TRUE, "正常") -> #NAME?
A14: 増減 | B14: =B13-$B18*$B$22 -> 37000 | C14: =C13-$B18*$B$22 -> 23000 | D14: =D13-$B18*$B$22 -> -60000 | E14: =IF(COUNTA(E$1), E13-$B18*$B$22, "-") -> - | F14: =SUM($B14:$E14) -> 0 | G14: -
A15: 清算 | B15: =B$14*$B$19 -> 1850 | C15: =C$14*$B$19 -> 1150 | D15: =D$14*$B$19 -> -3000 | E15: =IF(COUNTA(E$1), E$14*$B$19, "-") -> - | F15: =SUM($B15:$E15) -> 0 | G15: -
A16: 順位 | B16: =RANK(B$15, $B$15:$E$15) -> 1 | C16: =RANK(C$15, $B$15:$E$15) -> 2 | D16: =RANK(D$15, $B$15:$E$15) -> 3 | E16: =IF(COUNTA(E$1), RANK(E$15, $B$15:$E$15), "-") -> - | F16: =SUM($B16:$E16) -> 6 | G16: -
A18: 持ち点 | B18: 35000
A19: レート | B19: 0.05
A21: プレイヤー数 | B21: =COUNTA($B$1:$E$1) -> 3
A22: ゲーム数 | B22: =COUNT($B$2:$B$11) -> 10
A23: 合計点 | B23: =$B$18*$B$21*$B$22 -> 1050000

Sheet 20250630-2
A1: プレイヤー名 | B1: きむら | C1: かいと | D1: えいご | F1: 合計 | G1: 点数チェック
A2: 1 ゲーム目 | B2: -5000 | C2: 3000 | D2: 107000 | F2: =SUM($B2:$E2) -> 105000 | G2: =_xludf.IFS(COUNT($B2:$E2)=0, "", $F2>$B$17*$B$20, マスタ!$A$2, $F2<$B$17*$B$20, マスタ!$A$3, TRUE, "正常") -> #NAME?
A3: 2 ゲーム目 | B3: 24000 | C3: 38000 | D3: 43000 | F3: =SUM($B3:$E3) -> 105000 | G3: =_xludf.IFS(COUNT($B3:$E3)=0, "", $F3>$B$17*$B$20, マスタ!$A$2, $F3<$B$17*$B$20, マスタ!$A$3, TRUE, "正常") -> #NAME?
A4: 3 ゲーム目 | F4: =SUM($B4:$E4) -> 0 | G4: =_xludf.IFS(COUNT($B4:$E4)=0, "", $F4>$B$17*$B$20, マスタ!$A$2, $F4<$B$17*$B$20, マスタ!$A$3, TRUE, "正常") -> #NAME?
A5: 4 ゲーム目 | F5: =SUM($B5:$E5) -> 0 | G5: =_xludf.IFS(COUNT($B5:$E5)=0, "", $F5>$B$17*$B$20, マスタ!$A$2, $F5<$B$17*$B$20, マスタ!$A$3, TRUE, "正常") -> #NAME?
A6: 5 ゲーム目 | F6: =SUM($B6:$E6) -> 0 | G6: =_xludf.IFS(COUNT($B6:$E6)=0, "", $F6>$B$17*$B$20, マスタ!$A$2, $F6<$B$17*$B$20, マスタ!$A$3, TRUE, "正常") -> #NAME?
A7: 6 ゲーム目 | F7: =SUM($B7:$E7) -> 0 | G7: =_xludf.IFS(COUNT($B7:$E7)=0, "", $F7>$B$17*$B$20, マスタ!$A$2, $F7<$B$17*$B$20, マスタ!$A$3, TRUE, "正常") -> #NAME?
A8: 7 ゲーム目 | F8: =SUM($B8:$E8) -> 0 | G8: =_xludf.IFS(COUNT($B8:$E8)=0, "", $F8>$B$17*$B$20, マスタ!$A$2, $F8<$B$17*$B$20, マスタ!$A$3, TRUE, "正常") -> #NAME?
A9: 8 ゲーム目 | F9: =SUM($B9:$E9) -> 0 | G9: =_xludf.IFS(COUNT($B9:$E9)=0, "", $F9>$B$17*$B$20, マスタ!$A$2, $F9<$B$17*$B$20, マスタ!$A$3, TRUE, "正常") -> #NAME?
A10: 9 ゲーム目 | F10: =SUM($B10:$E10) -> 0 | G10: =_xludf.IFS(COUNT($B10:$E10)=0, "", $F10>$B$17*$B$20, マスタ!$A$2, $F10<$B$17*$B$20, マスタ!$A$3, TRUE, "正常") -> #NAME?
A11: 10 ゲーム目 | F11: =SUM($B11:$E11) -> 0 | G11: =_xludf.IFS(COUNT($B11:$E11)=0, "", $F11>$B$17*$B$20, マスタ!$A$2, $F11<$B$17*$B$20, マスタ!$A$3, TRUE, "正常") -> #NAME?
A12: 合計 | B12: =SUM(B$2:B$11) -> 19000 | C12: =SUM(C$2:C$11) -> 41000 | D12: =SUM(D$2:D$11) -> 150000 | E12: =IF(COUNTA(E$1), SUM(E$2:E$11), "-") -> - | F12: =SUM($B12:$E12) -> 210000 | G12: =_xludf.IFS($F$12>$B$17*$B$20*$B$21, マスタ!$A$2, $F$12<$B$17*$B$20*$B$21, マスタ!$A$3, TRUE, "正常") -> #NAME?
A13: 増減 | B13: =B12-$B17*$B$21 -> -51000 | C13: =C12-$B17*$B$21 -> -29000 | D13: =D12-$B17*$B$21 -> 80000 | E13: =IF(COUNTA(E$1), E12-$B17*$B$21, "-") -> - | F13: =SUM($B13:$E13) -> 0 | G13: -
A14: 清算 | B14: =B$13*$B$18 -> -2550 | C14: =C$13*$B$18 -> -1450 | D14: =D$13*$B$18 -> 4000 | E14: =IF(COUNTA(E$1), E$13*$B$18, "-") -> - | F14: =SUM($B14:$E14) -> 0 | G14: -
A15: 順位 | B15: =RANK(B$14, $B$14:$E$14) -> 3 | C15: =RANK(C$14, $B$14:$E$14) -> 2 | D15: =RANK(D$14, $B$14:$E$14) -> 1 | E15: =IF(COUNTA(E$1), RANK(E$14, $B$14:$E$14), "-") -> - | F15: =SUM($B15:$E15) -> 6 | G15: -
A17: 持ち点 | B17: 35000
A18: レート | B18: 0.05
A20: プレイヤー数 | B20: =COUNTA($B$1:$E$1) -> 3
A21: ゲーム数 | B21: =COUNT($B$2:$B$11) -> 2
A22: 合計点 | B22: =$B$17*$B$20*$B$21 -> 210000

Sheet 20250703
A1: プレイヤー名 | B1: おうた | C1: かいと | D1: えいご | E1: だいち | F1: 合計 | G1: 点数チェック
A2: 1 ゲーム目 | B2: 21900 | C2: 66400 | D2: -5300 | E2: 17000 | F2: =SUM($B2:$E2) -> 100000 | G2: =_xludf.IFS(COUNT($B2:$E2)=0, "", $F2>$B$17*$B$20, マスタ!$A$2, $F2<$B$17*$B$20, マスタ!$A$3, TRUE, "正常") -> #NAME?
A3: 2 ゲーム目 | B3: 22100 | C3: 17800 | D3: 39100 | E3: 21000 | F3: =SUM($B3:$E3) -> 100000 | G3: =_xludf.IFS(COUNT($B3:$E3)=0, "", $F3>$B$17*$B$20, マスタ!$A$2, $F3<$B$17*$B$20, マスタ!$A$3, TRUE, "正常") -> #NAME?
A4: 3 ゲーム目 | B4: 23400 | C4: 22000 | D4: 33600 | E4: 21000 | F4: =SUM($B4:$E4) -> 100000 | G4: =_xludf.IFS(COUNT($B4:$E4)=0, "", $F4>$B$17*$B$20, マスタ!$A$2, $F4<$B$17*$B$20, マスタ!$A$3, TRUE, "正常") -> #NAME?
A5: 4 ゲーム目 | F5: =SUM($B5:$E5) -> 0 | G5: =_xludf.IFS(COUNT($B5:$E5)=0, "", $F5>$B$17*$B$20, マスタ!$A$2, $F5<$B$17*$B$20, マスタ!$A$3, TRUE, "正常") -> #NAME?
A6: 5 ゲーム目 | F6: =SUM($B6:$E6) -> 0 | G6: =_xludf.IFS(COUNT($B6:$E6)=0, "", $F6>$B$17*$B$20, マスタ!$A$2, $F6<$B$17*$B$20, マスタ!$A$3, TRUE, "正常") -> #NAME?
A7: 6 ゲーム目 | F7: =SUM($B7:$E7) -> 0 | G7: =_xludf.IFS(COUNT($B7:$E7)=0, "", $F7>$B$17*$B$20, マスタ!$A$2, $F7<$B$17*$B$20, マスタ!$A$3, TRUE, "正常") -> #NAME?
A8: 7 ゲーム目 | F8: =SUM($B8:$E8) -> 0 | G8: =_xludf.IFS(COUNT($B8:$E8)=0, "", $F8>$B$17*$B$20, マスタ!$A$2, $F8<$B$17*$B$20, マスタ!$A$3, TRUE, "正常") -> #NAME?
A9: 8 ゲーム目 | F9: =SUM($B9:$E9) -> 0 | G9: =_xludf.IFS(COUNT($B9:$E9)=0, "", $F9>$B$17*$B$20, マスタ!$A$2, $F9<$B$17*$B$20, マスタ!$A$3, TRUE, "正常") -> #NAME?
A10: 9 ゲーム目 | F10: =SUM($B10:$E10) -> 0 | G10: =_xludf.IFS(COUNT($B10:$E10)=0, "", $F10>$B$17*$B$20, マスタ!$A$2, $F10<$B$17*$B$20, マスタ!$A$3, TRUE, "正常") -> #NAME?
A11: 10 ゲーム目 | F11: =SUM($B11:$E11) -> 0 | G11: =_xludf.IFS(COUNT($B11:$E11)=0, "", $F11>$B$17*$B$20, マスタ!$A$2, $F11<$B$17*$B$20, マスタ!$A$3, TRUE, "正常") -> #NAME?
A12: 合計 | B12: =SUM(B$2:B$11) -> 67400 | C12: =SUM(C$2:C$11) -> 106200 | D12: =SUM(D$2:D$11) -> 67400 | E12: =IF(COUNTA(E$1), SUM(E$2:E$11), "-") -> 59000 | F12: =SUM($B12:$E12) -> 300000 | G12: =_xludf.IFS($F$12>$B$17*$B$20*$B$21, マスタ!$A$2, $F$12<$B$17*$B$20*$B$21, マスタ!$A$3, TRUE, "正常") -> #NAME?
A13: 増減 | B13: =B12-$B17*$B$21 -> -7600 | C13: =C12-$B17*$B$21 -> 31200 | D13: =D12-$B17*$B$21 -> -7600 | E13: =IF(COUNTA(E$1), E12-$B17*$B$21, "-") -> -16000 | F13: =SUM($B13:$E13) -> 0 | G13: -
A14: 清算 | B14: =B$13*$B$18 -> -760 | C14: =C$13*$B$18 -> 3120 | D14: =D$13*$B$18 -> -760 | E14: =IF(COUNTA(E$1), E$13*$B$18, "-") -> -1600 | F14: =SUM($B14:$E14) -> 0 | G14: -
A15: 順位 | B15: =RANK(B$14, $B$14:$E$14) -> 2 | C15: =RANK(C$14, $B$14:$E$14) -> 1 | D15: =RANK(D$14, $B$14:$E$14) -> 2 | E15: =IF(COUNTA(E$1), RANK(E$14, $B$14:$E$14), "-") -> 4 | F15: =SUM($B15:$E15) -> 9 | G15: -
A17: 持ち点 | B17: 25000
A18: レート | B18: 0.1
A20: プレイヤー数 | B20: =COUNTA($B$1:$E$1) -> 4
A21: ゲーム数 | B21: =COUNT($B$2:$B$11) -> 3
A22: 合計点 | B22: =$B$17*$B$20*$B$21 -> 300000

Sheet 20250707
A1: プレイヤー名 | B1: だいち | C1: かいと | D1: えいご | F1: 合計 | G1: 点数チェック
A2: 1 ゲーム目 | B2: 42000 | C2: 70000 | D2: -7000 | F2: =SUM($B2:$E2) -> 105000 | G2: =_xludf.IFS(COUNT($B2:$E2)=0, "", $F2>$B$17*$B$20, マスタ!$A$2, $F2<$B$17*$B$20, マスタ!$A$3, TRUE, "正常") -> #NAME?
A3: 2 ゲーム目 | B3: 11000 | C3: 87000 | D3: 7000 | F3: =SUM($B3:$E3) -> 105000 | G3: =_xludf.IFS(COUNT($B3:$E3)=0, "", $F3>$B$17*$B$20, マスタ!$A$2, $F3<$B$17*$B$20, マスタ!$A$3, TRUE, "正常") -> #NAME?
A4: 3 ゲーム目 | B4: 6000 | C4: 75000 | D4: 24000 | F4: =SUM($B4:$E4) -> 105000 | G4: =_xludf.IFS(COUNT($B4:$E4)=0, "", $F4>$B$17*$B$20, マスタ!$A$2, $F4<$B$17*$B$20, マスタ!$A$3, TRUE, "正常") -> #NAME?
A5: 4 ゲーム目 | B5: 41000 | C5: 67000 | D5: -3000 | F5: =SUM($B5:$E5) -> 105000 | G5: =_xludf.IFS(COUNT($B5:$E5)=0, "", $F5>$B$17*$B$20, マスタ!$A$2, $F5<$B$17*$B$20, マスタ!$A$3, TRUE, "正常") -> #NAME?
A6: 5 ゲーム目 | B6: 77000 | C6: -3000 | D6: 31000 | F6: =SUM($B6:$E6) -> 105000 | G6: =_xludf.IFS(COUNT($B6:$E6)=0, "", $F6>$B$17*$B$20, マスタ!$A$2, $F6<$B$17*$B$20, マスタ!$A$3, TRUE, "正常") -> #NAME?
A7: 6 ゲーム目 | B7: 27000 | C7: 11000 | D7: 67000 | F7: =SUM($B7:$E7) -> 105000 | G7: =_xludf.IFS(COUNT($B7:$E7)=0, "", $F7>$B$17*$B$20, マスタ!$A$2, $F7<$B$17*$B$20, マスタ!$A$3, TRUE, "正常") -> #NAME?
A8: 7 ゲーム目 | B8: 88000 | C8: 9000 | D8: 8000 | F8: =SUM($B8:$E8) -> 105000 | G8: =_xludf.IFS(COUNT($B8:$E8)=0, "", $F8>$B$17*$B$20, マスタ!$A$2, $F8<$B$17*$B$20, マスタ!$A$3, TRUE, "正常") -> #NAME?
A9: 8 ゲーム目 | F9: =SUM($B9:$E9) -> 0 | G9: =_xludf.IFS(COUNT($B9:$E9)=0, "", $F9>$B$17*$B$20, マスタ!$A$2, $F9<$B$17*$B$20, マスタ!$A$3, TRUE, "正常") -> #NAME?
A10: 9 ゲーム目 | F10: =SUM($B10:$E10) -> 0 | G10: =_xludf.IFS(COUNT($B10:$E10)=0, "", $F10>$B$17*$B$20, マスタ!$A$2, $F10<$B$17*$B$20, マスタ!$A$3, TRUE, "正常") -> #NAME?
A11: 10 ゲーム目 | F11: =SUM($B11:$E11) -> 0 | G11: =_xludf.IFS(COUNT($B11:$E11)=0, "", $F11>$B$17*$B$20, マスタ!$A$2, $F11<$B$17*$B$20, マスタ!$A$3, TRUE, "正常") -> #NAME?
A12: 合計 | B12: =SUM(B$2:B$11) -> 292000 | C12: =SUM(C$2:C$11) -> 316000 | D12: =SUM(D$2:D$11) -> 127000 | E12: =IF(COUNTA(E$1), SUM(E$2:E$11), "-") -> - | F12: =SUM($B12:$E12) -> 735000 | G12: =_xludf.IFS($F$12>$B$17*$B$20*$B$21, マスタ!$A$2, $F$12<$B$17*$B$20*$B$21, マスタ!$A$3, TRUE, "正常") -> #NAME?
A13: 増減 | B13: =B12-$B17*$B$21 -> 47000 | C13: =C12-$B17*$B$21 -> 71000 | D13: =D12-$B17*$B$21 -> -118000 | E13: =IF(COUNTA(E$1), E12-$B17*$B$21, "-") -> - | F13: =SUM($B13:$E13) -> 0 | G13: -
A14: 清算 | B14: =B$13*$B$18 -> 2350 | C14: =C$13*$B$18 -> 3550 | D14: =D$13*$B$18 -> -5900 | E14: =IF(COUNTA(E$1), E$13*$B$18, "-") -> - | F14: =SUM($B14:$E14) -> 0 | G14: -
A15: 順位 | B15: =RANK(B$14, $B$14:$E$14) -> 2 | C15: =RANK(C$14, $B$14:$E$14) -> 1 | D15: =RANK(D$14, $B$14:$E$14) -> 3 | E15: =IF(COUNTA(E$1), RANK(E$14, $B$14:$E$14), "-") -> - | F15: =SUM($B15:$E15) -> 6 | G15: -
A17: 持ち点 | B17: 35000
A18: レート | B18: 0.05
A20: プレイヤー数 | B20: =COUNTA($B$1:$E$1) -> 3
A21: ゲーム数 | B21: =COUNT($B$2:$B$11) -> 7
A22: 合計点 | B22: =$B$17*$B$20*$B$21 -> 735000

Sheet 20250707四麻
A1: プレイヤー名 | B1: だいち | C1: かいと | D1: えいご | E1: きむら | F1: 合計 | G1: 点数チェック
A2: 1 ゲーム目 | B2: 26500 | C2: 34800 | D2: -3500 | E2: 42200 | F2: =SUM($B2:$E2) -> 100000 | G2: =_xludf.IFS(COUNT($B2:$E2)=0, "", $F2>$B$17*$B$20, マスタ!$A$2, $F2<$B$17*$B$20, マスタ!$A$3, TRUE, "正常") -> #NAME?
A3: 2 ゲーム目 | B3: 16500 | C3: 48000 | D3: 9500 | E3: 26000 | F3: =SUM($B3:$E3) -> 100000 | G3: =_xludf.IFS(COUNT($B3:$E3)=0, "", $F3>$B$17*$B$20, マスタ!$A$2, $F3<$B$17*$B$20, マスタ!$A$3, TRUE, "正常") -> #NAME?
A4: 3 ゲーム目 | F4: =SUM($B4:$E4) -> 0 | G4: =_xludf.IFS(COUNT($B4:$E4)=0, "", $F4>$B$17*$B$20, マスタ!$A$2, $F4<$B$17*$B$20, マスタ!$A$3, TRUE, "正常") -> #NAME?
A5: 4 ゲーム目 | F5: =SUM($B5:$E5) -> 0 | G5: =_xludf.IFS(COUNT($B5:$E5)=0, "", $F5>$B$17*$B$20, マスタ!$A$2, $F5<$B$17*$B$20, マスタ!$A$3, TRUE, "正常") -> #NAME?
A6: 5 ゲーム目 | F6: =SUM($B6:$E6) -> 0 | G6: =_xludf.IFS(COUNT($B6:$E6)=0, "", $F6>$B$17*$B$20, マスタ!$A$2, $F6<$B$17*$B$20, マスタ!$A$3, TRUE, "正常") -> #NAME?
A7: 6 ゲーム目 | F7: =SUM($B7:$E7) -> 0 | G7: =_xludf.IFS(COUNT($B7:$E7)=0, "", $F7>$B$17*$B$20, マスタ!$A$2, $F7<$B$17*$B$20, マスタ!$A$3, TRUE, "正常") -> #NAME?
A8: 7 ゲーム目 | F8: =SUM($B8:$E8) -> 0 | G8: =_xludf.IFS(COUNT($B8:$E8)=0, "", $F8>$B$17*$B$20, マスタ!$A$2, $F8<$B$17*$B$20, マスタ!$A$3, TRUE, "正常") -> #NAME?
A9: 8 ゲーム目 | F9: =SUM($B9:$E9) -> 0 | G9: =_xludf.IFS(COUNT($B9:$E9)=0, "", $F9>$B$17*$B$20, マスタ!$A$2, $F9<$B$17*$B$20, マスタ!$A$3, TRUE, "正常") -> #NAME?
A10: 9 ゲーム目 | F10: =SUM($B10:$E10) -> 0 | G10: =_xludf.IFS(COUNT($B10:$E10)=0, "", $F10>$B$17*$B$20, マスタ!$A$2, $F10<$B$17*$B$20, マスタ!$A$3, TRUE, "正常") -> #NAME?
A11: 10 ゲーム目 | F11: =SUM($B11:$E11) -> 0 | G11: =_xludf.IFS(COUNT($B11:$E11)=0, "", $F11>$B$17*$B$20, マスタ!$A$2, $F11<$B$17*$B$20, マスタ!$A$3, TRUE, "正常") -> #NAME?
A12: 合計 | B12: =SUM(B$2:B$11) -> 43000 | C12: =SUM(C$2:C$11) -> 82800 | D12: =SUM(D$2:D$11) -> 6000 | E12: =IF(COUNTA(E$1), SUM(E$2:E$11), "-") -> 68200 | F12: =SUM($B12:$E12) -> 200000 | G12: =_xludf.IFS($F$12>$B$17*$B$20*$B$21, マスタ!$A$2, $F$12<$B$17*$B$20*$B$21, マスタ!$A$3, TRUE, "正常") -> #NAME?
A13: 増減 | B13: =B12-$B17*$B$21 -> -7000 | C13: =C12-$B17*$B$21 -> 32800 | D13: =D12-$B17*$B$21 -> -44000 | E13: =IF(COUNTA(E$1), E12-$B17*$B$21, "-") -> 18200 | F13: =SUM($B13:$E13) -> 0 | G13: -
A14: 清算 | B14: =B$13*$B$18 -> -700 | C14: =C$13*$B$18 -> 3280 | D14: =D$13*$B$18 -> -4400 | E14: =IF(COUNTA(E$1), E$13*$B$18, "-") -> 1820 | F14: =SUM($B14:$E14) -> 0 | G14: -
A15: 順位 | B15: =RANK(B$14, $B$14:$E$14) -> 3 | C15: =RANK(C$14, $B$14:$E$14) -> 1 | D15: =RANK(D$14, $B$14:$E$14) -> 4 | E15: =IF(COUNTA(E$1), RANK(E$14, $B$14:$E$14), "-") -> 2 | F15: =SUM($B15:$E15) -> 10 | G15: -
A17: 持ち点 | B17: 25000
A18: レート | B18: 0.1
A20: プレイヤー数 | B20: =COUNTA($B$1:$E$1) -> 4
A21: ゲーム数 | B21: =COUNT($B$2:$B$11) -> 2
A22: 合計点 | B22: =$B$17*$B$20*$B$21 -> 200000

Sheet 20250716
A1: プレイヤー名 | B1: きむら | C1: かいと | D1: えいご | F1: 合計 | G1: 点数チェック
A2: 1 ゲーム目 | B2: 71000 | C2: 21000 | D2: 13000 | F2: =SUM($B2:$E2) -> 105000 | G2: =_xludf.IFS(COUNT($B2:$E2)=0, "", $F2>$B$17*$B$20, マスタ!$A$2, $F2<$B$17*$B$20, マスタ!$A$3, TRUE, "正常") -> #NAME?
A3: 2 ゲーム目 | B3: 74000 | C3: -4000 | D3: 35000 | F3: =SUM($B3:$E3) -> 105000 | G3: =_xludf.IFS(COUNT($B3:$E3)=0, "", $F3>$B$17*$B$20, マスタ!$A$2, $F3<$B$17*$B$20, マスタ!$A$3, TRUE, "正常") -> #NAME?
A4: 3 ゲーム目 | B4: 41000 | C4: 61000 | D4: 3000 | F4: =SUM($B4:$E4) -> 105000 | G4: =_xludf.IFS(COUNT($B4:$E4)=0, "", $F4>$B$17*$B$20, マスタ!$A$2, $F4<$B$17*$B$20, マスタ!$A$3, TRUE, "正常") -> #NAME?
A5: 4 ゲーム目 | B5: 58000 | C5: 62000 | D5: -15000 | F5: =SUM($B5:$E5) -> 105000 | G5: =_xludf.IFS(COUNT($B5:$E5)=0, "", $F5>$B$17*$B$20, マスタ!$A$2, $F5<$B$17*$B$20, マスタ!$A$3, TRUE, "正常") -> #NAME?
A6: 5 ゲーム目 | B6: 34000 | C6: 54000 | D6: 17000 | F6: =SUM($B6:$E6) -> 105000 | G6: =_xludf.IFS(COUNT($B6:$E6)=0, "", $F6>$B$17*$B$20, マスタ!$A$2, $F6<$B$17*$B$20, マスタ!$A$3, TRUE, "正常") -> #NAME?
A7: 6 ゲーム目 | F7: =SUM($B7:$E7) -> 0 | G7: =_xludf.IFS(COUNT($B7:$E7)=0, "", $F7>$B$17*$B$20, マスタ!$A$2, $F7<$B$17*$B$20, マスタ!$A$3, TRUE, "正常") -> #NAME?
A8: 7 ゲーム目 | F8: =SUM($B8:$E8) -> 0 | G8: =_xludf.IFS(COUNT($B8:$E8)=0, "", $F8>$B$17*$B$20, マスタ!$A$2, $F8<$B$17*$B$20, マスタ!$A$3, TRUE, "正常") -> #NAME?
A9: 8 ゲーム目 | F9: =SUM($B9:$E9) -> 0 | G9: =_xludf.IFS(COUNT($B9:$E9)=0, "", $F9>$B$17*$B$20, マスタ!$A$2, $F9<$B$17*$B$20, マスタ!$A$3, TRUE, "正常") -> #NAME?
A10: 9 ゲーム目 | F10: =SUM($B10:$E10) -> 0 | G10: =_xludf.IFS(COUNT($B10:$E10)=0, "", $F10>$B$17*$B$20, マスタ!$A$2, $F10<$B$17*$B$20, マスタ!$A$3, TRUE, "正常") -> #NAME?
A11: 10 ゲーム目 | F11: =SUM($B11:$E11) -> 0 | G11: =_xludf.IFS(COUNT($B11:$E11)=0, "", $F11>$B$17*$B$20, マスタ!$A$2, $F11<$B$17*$B$20, マスタ!$A$3, TRUE, "正常") -> #NAME?
A12: 合計 | B12: =SUM(B$2:B$11) -> 278000 | C12: =SUM(C$2:C$11) -> 194000 | D12: =SUM(D$2:D$11) -> 53000 | E12: =IF(COUNTA(E$1), SUM(E$2:E$11), "-") -> - | F12: =SUM($B12:$E12) -> 525000 | G12: =_xludf.IFS($F$12>$B$17*$B$20*$B$21, マスタ!$A$2, $F$12<$B$17*$B$20*$B$21, マスタ!$A$3, TRUE, "正常") -> #NAME?
A13: 増減 | B13: =B12-$B17*$B$21 -> 103000 | C13: =C12-$B17*$B$21 -> 19000 | D13: =D12-$B17*$B$21 -> -122000 | E13: =IF(COUNTA(E$1), E12-$B17*$B$21, "-") -> - | F13: =SUM($B13:$E13) -> 0 | G13: -
A14: 清算 | B14: =B$13*$B$18 -> 5150 | C14: =C$13*$B$18 -> 950 | D14: =D$13*$B$18 -> -6100 | E14: =IF(COUNTA(E$1), E$13*$B$18, "-") -> - | F14: =SUM($B14:$E14) -> 0 | G14: -
A15: 順位 | B15: =RANK(B$14, $B$14:$E$14) -> 1 | C15: =RANK(C$14, $B$14:$E$14) -> 2 | D15: =RANK(D$14, $B$14:$E$14) -> 3 | E15: =IF(COUNTA(E$1), RANK(E$14, $B$14:$E$14), "-") -> - | F15: =SUM($B15:$E15) -> 6 | G15: -
A17: 持ち点 | B17: 35000
A18: レート | B18: 0.05
A20: プレイヤー数 | B20: =COUNTA($B$1:$E$1) -> 3
A21: ゲーム数 | B21: =COUNT($B$2:$B$11) -> 5
A22: 合計点 | B22: =$B$17*$B$20*$B$21 -> 525000

Sheet 25250719 三麻
A1: プレイヤー名 | B1: きむら | C1: かいと | D1: だいち | F1: 合計 | G1: 点数チェック
